Workbook
Name in: Main!#REF!
Name in_1: Main!#REF!

Sheet Introduction
B3: DHWcalc 2.02 - Excel-Tool
B5: This tool helps the user to generate an ini-file which can be read by the program DHWcalc. The inputs saved in the ini-file can be re-loaded into the respective windows of the program. An ini-file for DHWcalc contains up to eight sections, which are initialized by an identifier enclosed in brackets e.g. [Main], representing the windows of the DHWcalc program. In each section values are stored and identified, by the respective identifier separated by an equal sign e.g. StartDay=1. In some cases the values in the ini-file are different from the values entered in the DHWcalc user interface or the orange fields of this excel-file, for example if Nr of categories = 4, the parameter BoxCateg s set to 1. The following seven sheets represent the windows of the DHWcalc program. All parameters are listed with name, value (orange cells) and, in some cases, an explanation. The orange cells are input fields. On the right the corresponding outputs are generated automatically. All outputs are listed again in the last sheet. In order to copy the green cells into the ini-file, click-and-hold the cell to the right of the green cells (white box) and pull the selection to the left. Copy the selection and paste it into the ini-file. This can either be a newly generated, empty text-file or an ini-file generated by DHWcalc. If sections or parameters are missing in an ini-file, the program will load default-values for these parameters.

Sheet Main
B2: Main Window | F2: Main | H2: [Main] | K2: Nr Categories | M2: Timestep in Minutes
B3: Household | C3: 0 | D3: 0 for Single Family Household, 1 for Multi Family Household | F3: SingleMulti | G3: =C3 -> 0 | H3: =CONCATENATE(F3,"=",G3) -> SingleMulti=0 | K3: 1 | L3: 0 | M3: 1 | N3: 0
B4: Nr. of Households | C4: 1 | F4: NoHH | G4: =C4 -> 1 | H4: =CONCATENATE(F4,"=",G4) -> NoHH=1 | K4: 4 | L4: 1 | M4: 3 | N4: 1
B5: Nr. of Categories | C5: 1 | D5: 1 or 4 | F5: BoxCateg | G5: =VLOOKUP(C5,K3:L4,2) -> 0 | H5: =CONCATENATE(F5,"=",G5) -> BoxCateg=0 | M5: 6 | N5: 2
B6: Timestep in minutes | C6: 1 | D6: 1, 3, 6, 10, 12, 15, 30 or 60 | F6: StepBox | G6: =VLOOKUP(C6,M3:N10,2) -> 0 | H6: =CONCATENATE(F6,"=",G6) -> StepBox=0 | M6: 10 | N6: 3
B7: Startday of profile | C7: 1 | F7: StartDay | G7: =C7 -> 1 | H7: =CONCATENATE(F7,"=",G7) -> StartDay=1 | M7: 12 | N7: 4
B8: Total duration | C8: 10 | D8: in days | F8: NrDays | G8: =C8 -> 10 | H8: =CONCATENATE(F8,"=",G8) -> NrDays=10 | M8: 15 | N8: 5
B9: Total mean daily draw-off volume | C9: 200.0 | D9: in l/d (decimal seperator: .) | F9: Vol | G9: =C9 -> 200.0 | H9: =CONCATENATE(F9,"=",G9) -> Vol=200.0 | M9: 30 | N9: 6
B10: Daylight saving time | C10: 0 | D10: 0 for applied, 1 for not applied | F10: Dls | G10: =C10 -> 0 | H10: =CONCATENATE(F10,"=",G10) -> Dls=0 | M10: 60 | N10: 7
B11: FileName | C11: DHW0001 | F11: FileName | G11: =C11 -> DHW0001 | H11: =CONCATENATE(F11,"=",G11) -> FileName=DHW0001

Sheet Prob
B2: Probability Distributions | G2: [Prob]
B3: Distribution during the day | C3: 1 | D3: 0 for DHW standard distribution, 1 for Step function for weekdays and weekends, 2 for Step function for each day (can be specified in "ProbTab") | F3: Day | G3: =CONCATENATE(F3,"=",C3) -> Day=1
B4: Probability weekend-day/weekday | C4: 120 | D4: 0-300 in % | F4: Week | G4: =CONCATENATE(F4,"=",C4) -> Week=120
B5: Amplitude of Sine | C5: 10 | D5: in % | F5: SinAmpl | G5: =CONCATENATE(F5,"=",C5) -> SinAmpl=10
B6: Sine Maximum | C6: 45 | D6: day of the year | F6: SinMax | G6: =CONCATENATE(F6,"=",C6) -> SinMax=45
B7: Step function for months | C7: 0 | D7: 0 for deactivated, 1 for activated - can be specified in "ProbYear" | F7: StepMon | G7: =CONCATENATE(F7,"=",C7) -> StepMon=0
B8: MFH Holidays
B9: Holiday Period MFH | C9: 1 | D9: 0 for deactivated, 1 for activated | F9: HolPeriodMul | G9: =CONCATENATE(F9,"=",C9) -> HolPeriodMul=1
B10: Relative Consumption during Holiday | C10: 0 | D10: in % between 0 and 100 | F10: relHol | G10: =CONCATENATE(F10,"=",C10) -> relHol=0
B11: Number of holidays per household | C11: 14 | F11: NrHol | G11: =CONCATENATE(F11,"=",C11) -> NrHol=14
B12: Start day | C12: 1 | D12: 1 to 31 | F12: HmultDay1 | G12: =CONCATENATE(F12,"=",I12) -> HmultDay1=0 | I12: =IF(C12>0,C12-1,0) -> 0
B13: Start month | C13: 7 | D13: 1 to 12 | F13: HmultMon1 | G13: =CONCATENATE(F13,"=",I13) -> HmultMon1=6 | I13: =IF(C13>0,C13-1,0) -> 6
B14: End day | C14: 1 | D14: 1 to 31 | F14: HmultDay2 | G14: =CONCATENATE(F14,"=",I14) -> HmultDay2=0 | I14: =IF(C14>0,C14-1,0) -> 0
B15: End month | C15: 9 | D15: 1 to 12 | F15: HmultMon2 | G15: =CONCATENATE(F15,"=",I15) -> HmultMon2=8 | I15: =IF(C15>0,C15-1,0) -> 8
B17: SFH Holidays
B18: Start Date | C18: End Date | D18: Relative Consumption in % | F18: HolCount | G18: =CONCATENATE(F18,"=",I18) -> HolCount=0 | I18: =SUM(I19:I38) -> 0
F19: HolNr.1 | G19: =IF(I19=1,(F19&"="&B19&" - "&C19&" -> "&D19&"%"),"") | I19: =IF(AND(B19<>"",C19<>"",D19<>""),1,0) -> 0
F20: HolNr.2 | G20: =IF(I20=1,(F20&"="&B20&" - "&C20&" -> "&D20&"%"),"") | I20: =IF(AND(B20<>"",C20<>"",D20<>""),1,0) -> 0
F21: HolNr.3 | G21: =IF(I21=1,(F21&"="&B21&" - "&C21&" -> "&D21&"%"),"") | I21: =IF(AND(B21<>"",C21<>"",D21<>""),1,0) -> 0
F22: HolNr.4 | G22: =IF(I22=1,(F22&"="&B22&" - "&C22&" -> "&D22&"%"),"") | I22: =IF(AND(B22<>"",C22<>"",D22<>""),1,0) -> 0
F23: HolNr.5 | G23: =IF(I23=1,(F23&"="&B23&" - "&C23&" -> "&D23&"%"),"") | I23: =IF(AND(B23<>"",C23<>"",D23<>""),1,0) -> 0
F24: HolNr.6 | G24: =IF(I24=1,(F24&"="&B24&" - "&C24&" -> "&D24&"%"),"") | I24: =IF(AND(B24<>"",C24<>"",D24<>""),1,0) -> 0
F25: HolNr.7 | G25: =IF(I25=1,(F25&"="&B25&" - "&C25&" -> "&D25&"%"),"") | I25: =IF(AND(B25<>"",C25<>"",D25<>""),1,0) -> 0
F26: HolNr.8 | G26: =IF(I26=1,(F26&"="&B26&" - "&C26&" -> "&D26&"%"),"") | I26: =IF(AND(B26<>"",C26<>"",D26<>""),1,0) -> 0
F27: HolNr.9 | G27: =IF(I27=1,(F27&"="&B27&" - "&C27&" -> "&D27&"%"),"") | I27: =IF(AND(B27<>"",C27<>"",D27<>""),1,0) -> 0
F28: HolNr.10 | G28: =IF(I28=1,(F28&"="&B28&" - "&C28&" -> "&D28&"%"),"") | I28: =IF(AND(B28<>"",C28<>"",D28<>""),1,0) -> 0
F29: HolNr.11 | G29: =IF(I29=1,(F29&"="&B29&" - "&C29&" -> "&D29&"%"),"") | I29: =IF(AND(B29<>"",C29<>"",D29<>""),1,0) -> 0
F30: HolNr.12 | G30: =IF(I30=1,(F30&"="&B30&" - "&C30&" -> "&D30&"%"),"") | I30: =IF(AND(B30<>"",C30<>"",D30<>""),1,0) -> 0
... F118: HolNr.100 | G118: =IF(I118=1,(F118&"="&B118&" - "&C118&" -> "&D118&"%"),"") | I118: =IF(AND(B118<>"",C118<>"",D118<>""),1,0) -> 0

Sheet ProbDay
B2: Weekdays
B3: Time interval | D3: Volume in % | H3: [ProbDay]
B4: =C9 -> 22:00 | C4: 06:30 | D4: 2 | F4: Interval1 | G4: =VLOOKUP(C4,$J$4:$K$51,2) -> 12 | H4: =F4&"="&G4 -> Interval1=12 | J4: 00:30 | K4: 0
B5: =C4 -> 06:30 | C5: 07:30 | D5: 50 | F5: Interval2 | G5: =VLOOKUP(C5,$J$4:$K$51,2) -> 14 | H5: =F5&"="&G5 -> Interval2=14 | J5: 01:00 | K5: 1
B6: =C5 -> 07:30 | C6: 12:00 | D6: 6 | F6: Interval3 | G6: =VLOOKUP(C6,$J$4:$K$51,2) -> 23 | H6: =F6&"="&G6 -> Interval3=23 | J6: 01:30 | K6: 2
B7: =C6 -> 12:00 | C7: 13:00 | D7: 16 | F7: Interval4 | G7: =VLOOKUP(C7,$J$4:$K$51,2) -> 25 | H7: =F7&"="&G7 -> Interval4=25 | J7: 02:00 | K7: 3
B8: =C7 -> 13:00 | C8: 18:00 | D8: 6 | F8: Interval5 | G8: =VLOOKUP(C8,$J$4:$K$51,2) -> 35 | H8: =F8&"="&G8 -> Interval5=35 | J8: 02:30 | K8: 4
B9: =C8 -> 18:00 | C9: 22:00 | D9: 20 | F9: Interval6 | G9: =VLOOKUP(C9,$J$4:$K$51,2) -> 43 | H9: =F9&"="&G9 -> Interval6=43 | J9: 03:00 | K9: 5
B10: Sum: | D10: =SUM(D4:D9) -> 100 | F10: Interval7 | G10: =VLOOKUP(C13,$J$4:$K$51,2) -> 13 | H10: =F10&"="&G10 -> Interval7=13 | J10: 03:30 | K10: 6
F11: Interval8 | G11: =VLOOKUP(C14,$J$4:$K$51,2) -> 17 | H11: =F11&"="&G11 -> Interval8=17 | J11: 04:00 | K11: 7
B12: Weekend-days | F12: Interval9 | G12: =VLOOKUP(C15,$J$4:$K$51,2) -> 29 | H12: =F12&"="&G12 -> Interval9=29 | J12: 04:30 | K12: 8
B13: =C18 -> 23:00 | C13: 07:00 | D13: 3 | F13: Interval10 | G13: =VLOOKUP(C16,$J$4:$K$51,2) -> 33 | H13: =F13&"="&G13 -> Interval10=33 | J13: 05:00 | K13: 9
B14: =C13 -> 07:00 | C14: 09:00 | D14: 14 | F14: Interval11 | G14: =VLOOKUP(C17,$J$4:$K$51,2) -> 39 | H14: =F14&"="&G14 -> Interval11=39 | J14: 05:30 | K14: 10
B15: =C14 -> 09:00 | C15: 15:00 | D15: 20 | F15: Interval12 | G15: =VLOOKUP(C18,$J$4:$K$51,2) -> 45 | H15: =F15&"="&G15 -> Interval12=45 | J15: 06:00 | K15: 11
B16: =C15 -> 15:00 | C16: 17:00 | D16: 20 | F16: vol1 | G16: =D4 -> 2 | H16: =F16&"="&G16 -> vol1=2 | J16: 06:30 | K16: 12
B17: =C16 -> 17:00 | C17: 20:00 | D17: 38 | F17: vol2 | G17: =D5 -> 50 | H17: =F17&"="&G17 -> vol2=50 | J17: 07:00 | K17: 13
B18: =C17 -> 20:00 | C18: 23:00 | D18: 5 | F18: vol3 | G18: =D6 -> 6 | H18: =F18&"="&G18 -> vol3=6 | J18: 07:30 | K18: 14
B19: Sum: | D19: =SUM(D13:D18) -> 100 | F19: vol4 | G19: =D7 -> 16 | H19: =F19&"="&G19 -> vol4=16 | J19: 08:00 | K19: 15
F20: vol5 | G20: =D8 -> 6 | H20: =F20&"="&G20 -> vol5=6 | J20: 08.30 | K20: 16
F21: vol6 | G21: =D9 -> 20 | H21: =F21&"="&G21 -> vol6=20 | J21: 09:00 | K21: 17
B22: Format for time input is hh:mm For minutes only 00 or 30 are allowed. The time 00:00 is not allowed, instead 24:00 is allowed. Every time input has to be higher than the previous. The sum of the daily Volume has to be 100 % | F22: vol7 | G22: =D13 -> 3 | H22: =F22&"="&G22 -> vol7=3 | J22: 09:30 | K22: 18
F23: vol8 | G23: =D14 -> 14 | H23: =F23&"="&G23 -> vol8=14 | J23: 10:00 | K23: 19
F24: vol9 | G24: =D15 -> 20 | H24: =F24&"="&G24 -> vol9=20 | J24: 10:30 | K24: 20
F25: vol10 | G25: =D16 -> 20 | H25: =F25&"="&G25 -> vol10=20 | J25: 11:00 | K25: 21
F26: vol11 | G26: =D17 -> 38 | H26: =F26&"="&G26 -> vol11=38 | J26: 11:30 | K26: 22
F27: vol12 | G27: =D18 -> 5 | H27: =F27&"="&G27 -> vol12=5 | J27: 12:00 | K27: 23
H28: Scroll=0 | J28: 12:30 | K28: 24
H29: Numb=1 | J29: 13:00 | K29: 25
J30: 13:30 | K30: 26
J31: 14:00 | K31: 27
J32: 14:30 | K32: 28
J33: 15:00 | K33: 29
J34: 15:30 | K34: 30
J35: 16:00 | K35: 31
J36: 16:30 | K36: 32
J37: 17:00 | K37: 33
J38: 17:30 | K38: 34
J39: 18:00 | K39: 35
J40: 18:30 | K40: 36
J41: 19:00 | K41: 37
...

Sheet ProbTab
B2: Step function for each day
C3: All values in l/h | N3: [ProbTab]
C4: Monday | D4: Tuesday | E4: Wednesday | F4: Thursday | G4: Friday | H4: Saturday | I4: Sunday | J4: Sum | L4: 0 | M4: =C5 -> 0 | N4: =CONCATENATE(L4,"=",M4) -> 0=0
B5: 0 | C5: 0 | D5: 0 | E5: 0 | F5: 0 | G5: 0 | H5: 0 | I5: 0 | J5: =SUM(C5:I5) -> 0 | L5: 1 | M5: =C6 -> 0 | N5: =CONCATENATE(L5,"=",M5) -> 1=0
B6: 0.041666667 | C6: 0 | D6: 0 | E6: 0 | F6: 0 | G6: 0 | H6: 0 | I6: 0 | J6: =SUM(C6:I6) -> 0 | L6: 2 | M6: =C7 -> 0 | N6: =CONCATENATE(L6,"=",M6) -> 2=0
B7: 0.083333333 | C7: 0 | D7: 0 | E7: 0 | F7: 0 | G7: 0 | H7: 0 | I7: 0 | J7: =SUM(C7:I7) -> 0 | L7: 3 | M7: =C8 -> 0 | N7: =CONCATENATE(L7,"=",M7) -> 3=0
B8: 0.125 | C8: 0 | D8: 0 | E8: 0 | F8: 0 | G8: 0 | H8: 0 | I8: 0 | J8: =SUM(C8:I8) -> 0 | L8: 4 | M8: =C9 -> 2.18 | N8: =CONCATENATE(L8,"=",M8) -> 4=2.18
B9: 0.16666667 | C9: 2.18 | D9: 2.18 | E9: 2.18 | F9: 2.18 | G9: 2.18 | H9: 4.36 | I9: 4.36 | J9: =SUM(C9:I9) -> 19.62 | L9: 5 | M9: =C10 -> 13.08 | N9: =CONCATENATE(L9,"=",M9) -> 5=13.08
B10: 0.20833333 | C10: 13.08 | D10: 13.08 | E10: 13.08 | F10: 13.08 | G10: 13.08 | H10: 19.63 | I10: 19.63 | J10: =SUM(C10:I10) -> 104.66 | L10: 6 | M10: =C11 -> 21.81 | N10: =CONCATENATE(L10,"=",M10) -> 6=21.81
B11: 0.25 | C11: 21.81 | D11: 21.81 | E11: 21.81 | F11: 21.81 | G11: 21.81 | H11: 32.71 | I11: 32.71 | J11: =SUM(C11:I11) -> 174.47 | L11: 7 | M11: =C12 -> 13.08 | N11: =CONCATENATE(L11,"=",M11) -> 7=13.08
B12: 0.29166667 | C12: 13.08 | D12: 13.08 | E12: 13.08 | F12: 13.08 | G12: 13.08 | H12: 19.63 | I12: 19.63 | J12: =SUM(C12:I12) -> 104.66 | L12: 8 | M12: =C13 -> 2.18 | N12: =CONCATENATE(L12,"=",M12) -> 8=2.18
B13: 0.33333333 | C13: 2.18 | D13: 2.18 | E13: 2.18 | F13: 2.18 | G13: 2.18 | H13: 2.18 | I13: 2.18 | J13: =SUM(C13:I13) -> 15.26 | L13: 9 | M13: =C14 -> 2.18 | N13: =CONCATENATE(L13,"=",M13) -> 9=2.18
B14: 0.375 | C14: 2.18 | D14: 2.18 | E14: 2.18 | F14: 2.18 | G14: 2.18 | H14: 2.18 | I14: 2.18 | J14: =SUM(C14:I14) -> 15.26 | L14: 10 | M14: =C15 -> 2.18 | N14: =CONCATENATE(L14,"=",M14) -> 10=2.18
B15: 0.41666667 | C15: 2.18 | D15: 2.18 | E15: 2.18 | F15: 2.18 | G15: 2.18 | H15: 2.18 | I15: 2.18 | J15: =SUM(C15:I15) -> 15.26 | L15: 11 | M15: =C16 -> 2.18 | N15: =CONCATENATE(L15,"=",M15) -> 11=2.18
B16: 0.45833333 | C16: 2.18 | D16: 2.18 | E16: 2.18 | F16: 2.18 | G16: 2.18 | H16: 2.18 | I16: 2.18 | J16: =SUM(C16:I16) -> 15.26 | L16: 12 | M16: =C17 -> 2.18 | N16: =CONCATENATE(L16,"=",M16) -> 12=2.18
... B26: 0.875 | C26: 2.18 | D26: 2.18 | E26: 2.18 | F26: 2.18 | G26: 2.18 | H26: 2.18 | I26: 2.18 | J26: =SUM(C26:I26) -> 15.26 | L26: 22 | M26: =C27 -> 0 | N26: =CONCATENATE(L26,"=",M26) -> 22=0
B27: 0.91666667 | C27: 0 | D27: 0 | E27: 0 | F27: 0 | G27: 0 | H27: 0 | I27: 0 | J27: =SUM(C27:I27) -> 0 | N27: =CONCATENATE(L28,"=",M28) -> 23=0
B28: 0.95833333 | C28: 0 | D28: 0 | E28: 0 | F28: 0 | G28: 0 | H28: 0 | I28: 0 | J28: =SUM(C28:I28) -> 0 | L28: 23 | M28: =C28 -> 0 | N28: =CONCATENATE(L29,"=",M29) -> 24=0
B29: Sum | C29: =SUM(C5:C28) -> 89.39 | D29: =SUM(D5:D28) -> 89.39 | E29: =SUM(E5:E28) -> 89.39 | F29: =SUM(F5:F28) -> 89.39 | G29: =SUM(G5:G28) -> 89.39 | H29: =SUM(H5:H28) -> 126.47 | I29: =SUM(I5:I28) -> 126.47 | J29: =SUM(J5:J28) -> 699.89 | L29: 24 | M29: =D5 -> 0 | N29: =CONCATENATE(L30,"=",M30) -> 25=0
L30: 25 | M30: =D6 -> 0 | N30: =CONCATENATE(L31,"=",M31) -> 26=0
B31: If the sum of all values is not 7 times the total mean daily draw-off volume it will be automatically normalized. For decimal numbers the decimal seperator has to be dot ("."). | L31: 26 | M31: =D7 -> 0 | N31: =CONCATENATE(L32,"=",M32) -> 27=0
L32: 27 | M32: =D8 -> 0 | N32: =CONCATENATE(L33,"=",M33) -> 28=2.18
L33: 28 | M33: =D9 -> 2.18 | N33: =CONCATENATE(L34,"=",M34) -> 29=13.08
L34: 29 | M34: =D10 -> 13.08 | N34: =CONCATENATE(L35,"=",M35) -> 30=21.81
L35: 30 | M35: =D11 -> 21.81 | N35: =CONCATENATE(L36,"=",M36) -> 31=13.08
L36: 31 | M36: =D12 -> 13.08 | N36: =CONCATENATE(L37,"=",M37) -> 32=2.18
L37: 32 | M37: =D13 -> 2.18 | N37: =CONCATENATE(L38,"=",M38) -> 33=2.18
L38: 33 | M38: =D14 -> 2.18 | N38: =CONCATENATE(L39,"=",M39) -> 34=2.18
L39: 34 | M39: =D15 -> 2.18 | N39: =CONCATENATE(L40,"=",M40) -> 35=2.18
L40: 35 | M40: =D16 -> 2.18 | N40: =CONCATENATE(L41,"=",M41) -> 36=2.18
L41: 36 | M41: =D17 -> 2.18 | N41: =CONCATENATE(L42,"=",M42) -> 37=2.18
L42: 37 | M42: =D18 -> 2.18 | N42: =CONCATENATE(L43,"=",M43) -> 38=2.18
L43: 38 | M43: =D19 -> 2.18 | N43: =CONCATENATE(L44,"=",M44) -> 39=2.18
... L52: 47 | M52: =D28 -> 0 | N52: =CONCATENATE(L53,"=",M53) -> 48=0
L53: 48 | M53: =E5 -> 0 | N53: =CONCATENATE(L54,"=",M54) -> 49=0
L54: 49 | M54: =E6 -> 0 | N54: =CONCATENATE(L55,"=",M55) -> 50=0
L55: 50 | M55: =E7 -> 0 | N55: =CONCATENATE(L56,"=",M56) -> 51=0
L56: 51 | M56: =E8 -> 0 | N56: =CONCATENATE(L57,"=",M57) -> 52=2.18
L57: 52 | M57: =E9 -> 2.18 | N57: =CONCATENATE(L58,"=",M58) -> 53=13.08
L58: 53 | M58: =E10 -> 13.08 | N58: =CONCATENATE(L59,"=",M59) -> 54=21.81
...

Sheet ProbYear
B2: Step function vor months
B3: Month | C3: Value (between 0 and 200) | F3: [Probyear]
B4: January | C4: 100 | E4: Scroll1 | F4: =E4&"="&C4 -> Scroll1=100
B5: February | C5: 100 | E5: Scroll2 | F5: =E5&"="&C5 -> Scroll2=100
B6: March | C6: 100 | E6: Scroll3 | F6: =E6&"="&C6 -> Scroll3=100
B7: April | C7: 100 | E7: Scroll4 | F7: =E7&"="&C7 -> Scroll4=100
B8: May | C8: 100 | E8: Scroll5 | F8: =E8&"="&C8 -> Scroll5=100
B9: June | C9: 100 | E9: Scroll6 | F9: =E9&"="&C9 -> Scroll6=100
B10: July | C10: 100 | E10: Scroll7 | F10: =E10&"="&C10 -> Scroll7=100
B11: August | C11: 100 | E11: Scroll8 | F11: =E11&"="&C11 -> Scroll8=100
B12: September | C12: 100 | E12: Scroll9 | F12: =E12&"="&C12 -> Scroll9=100
B13: October | C13: 100 | E13: Scroll10 | F13: =E13&"="&C13 -> Scroll10=100
B14: November | C14: 100 | E14: Scroll11 | F14: =E14&"="&C14 -> Scroll11=100
B15: December | C15: 100 | E15: Scroll12 | F15: =E15&"="&C15 -> Scroll12=100

Sheet Flow
B2: Flow rates etc.
B3: One Category | G3: [Flow1]
B4: mean flow rate per draw-off | C4: 480 | D4: in l/h | F4: mean | G4: =F4&"="&C4 -> mean=480
B5: duration of draw-off | C5: 1 | D5: in minutes | F5: dur | G5: =F5&"="&C5 -> dur=1
B6: standard deviation | C6: 120 | D6: in l/h | F6: sigma | G6: =F6&"="&C6 -> sigma=120
B7: min. flow rate | C7: 6 | D7: in l/h | F7: min | G7: =F7&"="&C7 -> min=6
B8: max. flow rate | C8: 1200 | D8: in l/h | F8: max | G8: =F8&"="&C8 -> max=1200
B10: Four Categories | G10: [Flow4]
B11: min. flow rate | C11: 1 | D11: in l/h | F11: min | G11: =F11&"="&C11 -> min=1
B12: max. flow rate | C12: 1200 | D12: in l/h | F12: max | G12: =F12&"="&C12 -> max=1200
B13: Category 1
B14: mean flow rate per draw-off | C14: 60 | D14: in l/h | F14: mean1 | G14: =F14&"="&C14 -> mean1=60
B15: duration of draw-off | C15: 1 | D15: in minutes | F15: dur1 | G15: =F15&"="&C15 -> dur1=1
B16: portion | C16: 14 | D16: in %, all 4 categories must combine to 100 % | F16: portion1 | G16: =F16&"="&C16 -> portion1=14
B17: standard deviation | C17: 120 | D17: in l/h | F17: sigma1 | G17: =F17&"="&C17 -> sigma1=120
B18: Category 2
B19: mean flow rate per draw-off | C19: 360 | D19: in l/h | F19: mean2 | G19: =F19&"="&C19 -> mean2=360
B20: duration of draw-off | C20: 1 | D20: in minutes | F20: dur2 | G20: =F20&"="&C20 -> dur2=1
B21: portion | C21: 36 | D21: in %, all 4 categories must combine to 100 % | F21: portion2 | G21: =F21&"="&C21 -> portion2=36
B22: standard deviation | C22: 120 | D22: in l/h | F22: sigma2 | G22: =F22&"="&C22 -> sigma2=120
B23: Category 3
B24: mean flow rate per draw-off | C24: 840 | D24: in l/h | F24: mean3 | G24: =F24&"="&C24 -> mean3=840
B25: duration of draw-off | C25: 10 | D25: in minutes | F25: dur3 | G25: =F25&"="&C25 -> dur3=10
B26: portion | C26: 10 | D26: in %, all 4 categories must combine to 100 % | F26: portion3 | G26: =F26&"="&C26 -> portion3=10
B27: standard deviation | C27: 12 | D27: in l/h | F27: sigma3 | G27: =F27&"="&C27 -> sigma3=12
B28: Category 4
B29: mean flow rate per draw-off | C29: 480 | D29: in l/h | F29: mean4 | G29: =F29&"="&C29 -> mean4=480
B30: duration of draw-off | C30: 5 | D30: in minutes | F30: dur4 | G30: =F30&"="&C30 -> dur4=5
B31: portion | C31: 40 | D31: in %, all 4 categories must combine to 100 % | F31: portion4 | G31: =F31&"="&C31 -> portion4=40
B32: standard deviation | C32: 24 | D32: in l/h | F32: sigma4 | G32: =F32&"="&C32 -> sigma4=24

Sheet ParVar
B2: Parameter variation
B3: Parameter to variate | C3: 1 | D3: 1: mean draw-off volume, 2: max flow rate, 3: mean flow rate | H3: [Par]
B4: Mean draw-off volume | F4: MeanVol= | G4: =IF(C3=1,1,0) -> 1 | H4: =F4&G4 -> MeanVol=1
B5: min. Volume | C5: 195 | D5: in l/day | F5: MaxFlow= | G5: =C5 -> 195 | H5: =F7&G5 -> VolMin=195
B6: max. Volume | C6: 205 | D6: in l/day | F6: MeanFlow= | G6: =C6 -> 205 | H6: =F8&G6 -> VolMax=205
B7: Volume step | C7: 2 | D7: in l/day | F7: VolMin= | G7: =C7 -> 2 | H7: =F9&G7 -> VolStep=2
B8: Max flow rate | F8: VolMax= | G8: =IF(C3=2,1,0) -> 0 | H8: =F5&G8 -> MaxFlow=0
B9: first max. flow rate | C9: 1000 | D9: in l/h | F9: VolStep= | G9: =C9 -> 1000 | H9: =F10&G9 -> MaxFirst=1000
B10: last max. flow rate | C10: 1400 | D10: in l/h | F10: MaxFirst= | G10: =C10 -> 1400 | H10: =F11&G10 -> MaxLast=1400
B11: max flow rate step | C11: 100 | D11: in l/h | F11: MaxLast= | G11: =C11 -> 100 | H11: =F12&G11 -> MaxStep=100
B12: Mean flow rate | F12: MaxStep= | G12: =IF(C3=3,1,0) -> 0 | H12: =F6&G12 -> MeanFlow=0
B13: min. mean flow rate | C13: 300 | D13: in l/h | F13: FlowMin= | G13: =C13 -> 300 | H13: =F13&G13 -> FlowMin=300
B14: max. mean flow rate | C14: 500 | D14: in l/h | F14: FlowMax= | G14: =C14 -> 500 | H14: =F14&G14 -> FlowMax=500
B15: mean flow rate step | C15: 50 | D15: in l/h | F15: FlowStep= | G15: =C15 -> 50 | H15: =F15&G15 -> FlowStep=50

Sheet Output
D2: =Main!H2 -> [Main]
D3: =Main!H3 -> SingleMulti=0 | F3: <- click this Cell and pull the selection to the left to copy all lines
D4: =Main!H4 -> NoHH=1
D5: =Main!H5 -> BoxCateg=0
D6: =Main!H6 -> StepBox=0
D7: =Main!H7 -> StartDay=1
D8: =Main!H8 -> NrDays=10
D9: =Main!H9 -> Vol=200.0
D10: =Main!H10 -> Dls=0
D11: =Main!H11 -> FileName=DHW0001
D13: =ProbYear!F3 -> [Probyear]
D14: =ProbYear!F4 -> Scroll1=100
D15: =ProbYear!F5 -> Scroll2=100
D16: =ProbYear!F6 -> Scroll3=100
D17: =ProbYear!F7 -> Scroll4=100
D18: =ProbYear!F8 -> Scroll5=100
D19: =ProbYear!F9 -> Scroll6=100
D20: =ProbYear!F10 -> Scroll7=100
D21: =ProbYear!F11 -> Scroll8=100
D22: =ProbYear!F12 -> Scroll9=100
D23: =ProbYear!F13 -> Scroll10=100
D24: =ProbYear!F14 -> Scroll11=100
D25: =ProbYear!F15 -> Scroll12=100
D27: =Flow!G3 -> [Flow1]
D28: =Flow!G4 -> mean=480
D29: =Flow!G5 -> dur=1
D30: =Flow!G6 -> sigma=120
D31: =Flow!G7 -> min=6
D32: =Flow!G8 -> max=1200
D34: =Flow!G10 -> [Flow4]
D35: =Flow!G11 -> min=1
D36: =Flow!G12 -> max=1200
D38: =Flow!G14 -> mean1=60
D39: =Flow!G15 -> dur1=1
D40: =Flow!G16 -> portion1=14
... D56: =Flow!G32 -> sigma4=24
D58: =ParVar!H3 -> [Par]
D59: =ParVar!H4 -> MeanVol=1
D60: =ParVar!H8 -> MaxFlow=0
D61: =ParVar!H12 -> MeanFlow=0
...
