Workbook
Name Gemeenten_alfabetisch_2022: 'municipalities per province'!#REF!
Name postcode: #REF!

Sheet municipalities
A1: gwb_code_10 | B1: gwb_code_8 | C1: regio | D1: gm_naam | E1: recs | F1: gwb_code | G1: province | H1: province_code | I1: RES_region | J1: RES_code | K1: longitude | L1: latitude | M1: ind_wbi | N1: a_inw | O1: a_man | P1: a_vrouw | Q1: ste_mvs | R1: ste_oad | S1: p_koopw | T1: p_huurw | U1: g_hh_sti_2021 | V1: p_hh_osm_2021 | W1: p_hh_110_2021 | X1: p_hh_120_2021 | Y1: m_hh_ver_2021 | Z1: wind_potential_nb_turbines | AA1: wind_potential_MW_turbines | AB1: wind_potential_GWh_turbines | AC1: pv_rooftop_potential_MW | AD1: pv_rooftop_potential_GWh | AE1: pv_field_potential_MW | AF1: pv_field_potential_GWh
A2: GM0014 | B2: 0014 | C2: Groningen | D2: Groningen | E2: Gemeente | F2: GM0014 | G2: {=INDEX('municipalities per province'!F:F,MATCH(municipalities!$A2,'municipalities per province'!$B:$B,0),0)} -> Groningen | H2: {=INDEX('municipalities per province'!E:E,MATCH(municipalities!$A2,'municipalities per province'!$B:$B,0),0)} -> PV20 | I2: {=INDEX('municipalities per province'!G:G,MATCH(municipalities!$A2,'municipalities per province'!$B:$B,0),0)} -> Groningen | J2: {=INDEX('municipalities per province'!H:H,MATCH(municipalities!$A2,'municipalities per province'!$B:$B,0),0)} -> ES01 | K2: {=INDEX(coordinates!C:C,MATCH(municipalities!$A2,coordinates!$A:$A,0),0)} -> 6.6206669 | L2: {=INDEX(coordinates!D:D,MATCH(municipalities!$A2,coordinates!$A:$A,0),0)} -> 53.218625 | M2: 1 | N2: 238147 | O2: 118198 | P2: 119949 | Q2: 1 | R2: 3427 | S2: 40 | T2: 60 | U2: =IF(AJ2<0,AVERAGEIF(AJ:AJ,">0"),AJ2) -> 26.8 | V2: =IF(AK2<0,AVERAGEIF(AK:AK,">0"),AK2) -> 11 | W2: =IF(AL2<0,AVERAGEIF(AL:AL,">0"),AL2) -> 16 | X2: =IF(AM2<0,AVERAGEIF(AM:AM,">0"),AM2) -> 18.9 | Y2: =IF(AN2<0,AVERAGEIF(AN:AN,">0"),AN2) -> 11 | Z2: {=INDEX(municipality_wind_potential!$X:$X,MATCH(municipalities!$F2,municipality_wind_potential!$E:$E,0),0)} -> 60 | AA2: =Z2*$AH$2 -> 336 | AB2: {=INDEX(municipality_wind_potential!$Y:$Y,MATCH(municipalities!$F2,municipality_wind_potential!$E:$E,0),0) / 3.6} -> 1114.0917 | AC2: =AD2/$AH$3*1000 -> 252.19822 | AD2: {=INDEX(municipality_pv_potential!$G:$G,MATCH(municipalities!$A2,municipality_pv_potential!$E:$E,0),0)/3.6*$AH$4} -> 233.53556 | AE2: =AF2/$AH$3*1000 -> 467.16763 | AF2: {=INDEX(municipality_pv_potential!$H:$H,MATCH(municipalities!$A2,municipality_pv_potential!$E:$E,0),0)/3.6} -> 432.59722 | AG2: power per turbine wind | AH2: 5.6 | AI2: MW | AJ2: 26.8 | AK2: 11 | AL2: 16 | AM2: 18.9 | AN2: 11
A3: GM0034 | B3: 0034 | C3: Almere | D3: Almere | E3: Gemeente | F3: GM0034 | G3: {=INDEX('municipalities per province'!F:F,MATCH(municipalities!A3,'municipalities per province'!B:B,0),0)} -> Flevoland | H3: {=INDEX('municipalities per province'!E:E,MATCH(municipalities!$A3,'municipalities per province'!$B:$B,0),0)} -> PV24 | I3: {=INDEX('municipalities per province'!G:G,MATCH(municipalities!$A3,'municipalities per province'!$B:$B,0),0)} -> Flevoland | J3: {=INDEX('municipalities per province'!H:H,MATCH(municipalities!$A3,'municipalities per province'!$B:$B,0),0)} -> ES06 | K3: {=INDEX(coordinates!C:C,MATCH(municipalities!$A3,coordinates!$A:$A,0),0)} -> 5.1533874 | L3: {=INDEX(coordinates!D:D,MATCH(municipalities!$A3,coordinates!$A:$A,0),0)} -> 52.447426 | M3: 1 | N3: 222825 | O3: 110589 | P3: 112236 | Q3: 2 | R3: 1629 | S3: 63 | T3: 37 | U3: =IF(AJ3<0,AVERAGEIF(AJ:AJ,">0"),AJ3) -> 33.3 | V3: =IF(AK3<0,AVERAGEIF(AK:AK,">0"),AK3) -> 6.4 | W3: =IF(AL3<0,AVERAGEIF(AL:AL,">0"),AL3) -> 9.4 | X3: =IF(AM3<0,AVERAGEIF(AM:AM,">0"),AM3) -> 11.6 | Y3: =IF(AN3<0,AVERAGEIF(AN:AN,">0"),AN3) -> 91.9 | Z3: {=INDEX(municipality_wind_potential!$X:$X,MATCH(municipalities!$F3,municipality_wind_potential!$E:$E,0),0)} -> 62 | AA3: =Z3*$AH$2 -> 347.2 | AB3: {=INDEX(municipality_wind_potential!$Y:$Y,MATCH(municipalities!$F3,municipality_wind_potential!$E:$E,0),0) / 3.6} -> 1091.7472 | AC3: =AD3/$AH$3*1000 -> 208.58171 | AD3: {=INDEX(municipality_pv_potential!$G:$G,MATCH(municipalities!$A3,municipality_pv_potential!$E:$E,0),0)/3.6*$AH$4} -> 193.14667 | AE3: =AF3/$AH$3*1000 -> 147.84617 | AF3: {=INDEX(municipality_pv_potential!$H:$H,MATCH(municipalities!$A3,municipality_pv_potential!$E:$E,0),0)/3.6} -> 136.90556 | AG3: full load hour PV | AH3: =926 -> 926 | AI3: hour | AJ3: 33.3 | AK3: 6.4 | AL3: 9.4 | AM3: 11.6 | AN3: 91.9
A4: GM0037 | B4: 0037 | C4: Stadskanaal | D4: Stadskanaal | E4: Gemeente | F4: GM0037 | G4: {=INDEX('municipalities per province'!F:F,MATCH(municipalities!A4,'municipalities per province'!B:B,0),0)} -> Groningen | H4: {=INDEX('municipalities per province'!E:E,MATCH(municipalities!$A4,'municipalities per province'!$B:$B,0),0)} -> PV20 | I4: {=INDEX('municipalities per province'!G:G,MATCH(municipalities!$A4,'municipalities per province'!$B:$B,0),0)} -> Groningen | J4: {=INDEX('municipalities per province'!H:H,MATCH(municipalities!$A4,'municipalities per province'!$B:$B,0),0)} -> ES01 | K4: {=INDEX(coordinates!C:C,MATCH(municipalities!$A4,coordinates!$A:$A,0),0)} -> 7.0103221 | L4: {=INDEX(coordinates!D:D,MATCH(municipalities!$A4,coordinates!$A:$A,0),0)} -> 53.002171 | M4: 1 | N4: 32135 | O4: 15844 | P4: 16291 | Q4: 4 | R4: 840 | S4: 60 | T4: 39 | U4: =IF(AJ4<0,AVERAGEIF(AJ:AJ,">0"),AJ4) -> 28.7 | V4: =IF(AK4<0,AVERAGEIF(AK:AK,">0"),AK4) -> 7.5 | W4: =IF(AL4<0,AVERAGEIF(AL:AL,">0"),AL4) -> 12.6 | X4: =IF(AM4<0,AVERAGEIF(AM:AM,">0"),AM4) -> 17.1 | Y4: =IF(AN4<0,AVERAGEIF(AN:AN,">0"),AN4) -> 55.5 | Z4: {=INDEX(municipality_wind_potential!$X:$X,MATCH(municipalities!$F4,municipality_wind_potential!$E:$E,0),0)} -> 60 | AA4: =Z4*$AH$2 -> 336 | AB4: {=INDEX(municipality_wind_potential!$Y:$Y,MATCH(municipalities!$F4,municipality_wind_potential!$E:$E,0),0) / 3.6} -> 1056.2444 | AC4: =AD4/$AH$3*1000 -> 69.290857 | AD4: {=INDEX(municipality_pv_potential!$G:$G,MATCH(municipalities!$A4,municipality_pv_potential!$E:$E,0),0)/3.6*$AH$4} -> 64.163333 | AE4: =AF4/$AH$3*1000 -> 389.9628 | AF4: {=INDEX(municipality_pv_potential!$H:$H,MATCH(municipalities!$A4,municipality_pv_potential!$E:$E,0),0)/3.6} -> 361.10556 | AG4: share rooftop utility | AH4: 0.2 | AJ4: 28.7 | AK4: 7.5 | AL4: 12.6 | AM4: 17.1 | AN4: 55.5
A5: GM0047 | B5: 0047 | C5: Veendam | D5: Veendam | E5: Gemeente | F5: GM0047 | G5: {=INDEX('municipalities per province'!F:F,MATCH(municipalities!A5,'municipalities per province'!B:B,0),0)} -> Groningen | H5: {=INDEX('municipalities per province'!E:E,MATCH(municipalities!$A5,'municipalities per province'!$B:$B,0),0)} -> PV20 | I5: {=INDEX('municipalities per province'!G:G,MATCH(municipalities!$A5,'municipalities per province'!$B:$B,0),0)} -> Groningen | J5: {=INDEX('municipalities per province'!H:H,MATCH(municipalities!$A5,'municipalities per province'!$B:$B,0),0)} -> ES01 | K5: {=INDEX(coordinates!C:C,MATCH(municipalities!$A5,coordinates!$A:$A,0),0)} -> 6.8800916 | L5: {=INDEX(coordinates!D:D,MATCH(municipalities!$A5,coordinates!$A:$A,0),0)} -> 53.08899 | M5: 1 | N5: 27616 | O5: 13863 | P5: 13753 | Q5: 3 | R5: 1013 | S5: 65 | T5: 35 | U5: =IF(AJ5<0,AVERAGEIF(AJ:AJ,">0"),AJ5) -> 29.5 | V5: =IF(AK5<0,AVERAGEIF(AK:AK,">0"),AK5) -> 7.1 | W5: =IF(AL5<0,AVERAGEIF(AL:AL,">0"),AL5) -> 11.7 | X5: =IF(AM5<0,AVERAGEIF(AM:AM,">0"),AM5) -> 15.4 | Y5: =IF(AN5<0,AVERAGEIF(AN:AN,">0"),AN5) -> 46.6 | Z5: {=INDEX(municipality_wind_potential!$X:$X,MATCH(municipalities!$F5,municipality_wind_potential!$E:$E,0),0)} -> 40 | AA5: =Z5*$AH$2 -> 224 | AB5: {=INDEX(municipality_wind_potential!$Y:$Y,MATCH(municipalities!$F5,municipality_wind_potential!$E:$E,0),0) / 3.6} -> 701.20278 | AC5: =AD5/$AH$3*1000 -> 61.567075 | AD5: {=INDEX(municipality_pv_potential!$G:$G,MATCH(municipalities!$A5,municipality_pv_potential!$E:$E,0),0)/3.6*$AH$4} -> 57.011111 | AE5: =AF5/$AH$3*1000 -> 262.94996 | AF5: {=INDEX(municipality_pv_potential!$H:$H,MATCH(municipalities!$A5,municipality_pv_potential!$E:$E,0),0)/3.6} -> 243.49167 | AJ5: 29.5 | AK5: 7.1 | AL5: 11.7 | AM5: 15.4 | AN5: 46.6
A6: GM0050 | B6: 0050 | C6: Zeewolde | D6: Zeewolde | E6: Gemeente | F6: GM0050 | G6: {=INDEX('municipalities per province'!F:F,MATCH(municipalities!A6,'municipalities per province'!B:B,0),0)} -> Flevoland | H6: {=INDEX('municipalities per province'!E:E,MATCH(municipalities!$A6,'municipalities per province'!$B:$B,0),0)} -> PV24 | I6: {=INDEX('municipalities per province'!G:G,MATCH(municipalities!$A6,'municipalities per province'!$B:$B,0),0)} -> Flevoland | J6: {=INDEX('municipalities per province'!H:H,MATCH(municipalities!$A6,'municipalities per province'!$B:$B,0),0)} -> ES06 | K6: {=INDEX(coordinates!C:C,MATCH(municipalities!$A6,coordinates!$A:$A,0),0)} -> 5.5205362 | L6: {=INDEX(coordinates!D:D,MATCH(municipalities!$A6,coordinates!$A:$A,0),0)} -> 52.319162 | M6: 1 | N6: 23692 | O6: 12003 | P6: 11689 | Q6: 4 | R6: 842 | S6: 70 | T6: 30 | U6: =IF(AJ6<0,AVERAGEIF(AJ:AJ,">0"),AJ6) -> 35.3 | V6: =IF(AK6<0,AVERAGEIF(AK:AK,">0"),AK6) -> 4 | W6: =IF(AL6<0,AVERAGEIF(AL:AL,">0"),AL6) -> 6.2 | X6: =IF(AM6<0,AVERAGEIF(AM:AM,">0"),AM6) -> 7.9 | Y6: =IF(AN6<0,AVERAGEIF(AN:AN,">0"),AN6) -> 105.1 | Z6: {=INDEX(municipality_wind_potential!$X:$X,MATCH(municipalities!$F6,municipality_wind_potential!$E:$E,0),0)} -> 202 | AA6: =Z6*$AH$2 -> 1131.2 | AB6: {=INDEX(municipality_wind_potential!$Y:$Y,MATCH(municipalities!$F6,municipality_wind_potential!$E:$E,0),0) / 3.6} -> 3249.7917 | AC6: =AD6/$AH$3*1000 -> 71.49868 | AD6: {=INDEX(municipality_pv_potential!$G:$G,MATCH(municipalities!$A6,municipality_pv_potential!$E:$E,0),0)/3.6*$AH$4} -> 66.207778 | AE6: =AF6/$AH$3*1000 -> 868.61651 | AF6: {=INDEX(municipality_pv_potential!$H:$H,MATCH(municipalities!$A6,municipality_pv_potential!$E:$E,0),0)/3.6} -> 804.33889 | AJ6: 35.3 | AK6: 4 | AL6: 6.2 | AM6: 7.9 | AN6: 105.1
A7: GM0059 | B7: 0059 | C7: Achtkarspelen | D7: Achtkarspelen | E7: Gemeente | F7: GM0059 | G7: {=INDEX('municipalities per province'!F:F,MATCH(municipalities!A7,'municipalities per province'!B:B,0),0)} -> Friesland | H7: {=INDEX('municipalities per province'!E:E,MATCH(municipalities!$A7,'municipalities per province'!$B:$B,0),0)} -> PV21 | I7: {=INDEX('municipalities per province'!G:G,MATCH(municipalities!$A7,'municipalities per province'!$B:$B,0),0)} -> Friesland | J7: {=INDEX('municipalities per province'!H:H,MATCH(municipalities!$A7,'municipalities per province'!$B:$B,0),0)} -> ES02 | K7: {=INDEX(coordinates!C:C,MATCH(municipalities!$A7,coordinates!$A:$A,0),0)} -> 6.1431363 | L7: {=INDEX(coordinates!D:D,MATCH(municipalities!$A7,coordinates!$A:$A,0),0)} -> 53.21668 | M7: 1 | N7: 28149 | O7: 14352 | P7: 13797 | Q7: 5 | R7: 437 | S7: 64 | T7: 36 | U7: =IF(AJ7<0,AVERAGEIF(AJ:AJ,">0"),AJ7) -> 29.6 | V7: =IF(AK7<0,AVERAGEIF(AK:AK,">0"),AK7) -> 6.5 | W7: =IF(AL7<0,AVERAGEIF(AL:AL,">0"),AL7) -> 10.7 | X7: =IF(AM7<0,AVERAGEIF(AM:AM,">0"),AM7) -> 14 | Y7: =IF(AN7<0,AVERAGEIF(AN:AN,">0"),AN7) -> 101.4 | Z7: {=INDEX(municipality_wind_potential!$X:$X,MATCH(municipalities!$F7,municipality_wind_potential!$E:$E,0),0)} -> 44 | AA7: =Z7*$AH$2 -> 246.4 | AB7: {=INDEX(municipality_wind_potential!$Y:$Y,MATCH(municipalities!$F7,municipality_wind_potential!$E:$E,0),0) / 3.6} -> 862.4 | AC7: =AD7/$AH$3*1000 -> 70.11939 | AD7: {=INDEX(municipality_pv_potential!$G:$G,MATCH(municipalities!$A7,municipality_pv_potential!$E:$E,0),0)/3.6*$AH$4} -> 64.930556 | AE7: =AF7/$AH$3*1000 -> 362.461 | AF7: {=INDEX(municipality_pv_potential!$H:$H,MATCH(municipalities!$A7,municipality_pv_potential!$E:$E,0),0)/3.6} -> 335.63889 | AJ7: 29.6 | AK7: 6.5 | AL7: 10.7 | AM7: 14 | AN7: 101.4
A8: GM0060 | B8: 0060 | C8: Ameland | D8: Ameland | E8: Gemeente | F8: GM0060 | G8: {=INDEX('municipalities per province'!F:F,MATCH(municipalities!A8,'municipalities per province'!B:B,0),0)} -> Friesland | H8: {=INDEX('municipalities per province'!E:E,MATCH(municipalities!$A8,'municipalities per province'!$B:$B,0),0)} -> PV21 | I8: {=INDEX('municipalities per province'!G:G,MATCH(municipalities!$A8,'municipalities per province'!$B:$B,0),0)} -> Friesland | J8: {=INDEX('municipalities per province'!H:H,MATCH(municipalities!$A8,'municipalities per province'!$B:$B,0),0)} -> ES02 | K8: {=INDEX(coordinates!C:C,MATCH(municipalities!$A8,coordinates!$A:$A,0),0)} -> 5.7646773 | L8: {=INDEX(coordinates!D:D,MATCH(municipalities!$A8,coordinates!$A:$A,0),0)} -> 53.425341 | M8: 1 | N8: 3840 | O8: 1938 | P8: 1902 | Q8: 5 | R8: 266 | S8: 66 | T8: 34 | U8: =IF(AJ8<0,AVERAGEIF(AJ:AJ,">0"),AJ8) -> 34.730631 | V8: =IF(AK8<0,AVERAGEIF(AK:AK,">0"),AK8) -> 3.9 | W8: =IF(AL8<0,AVERAGEIF(AL:AL,">0"),AL8) -> 5.7 | X8: =IF(AM8<0,AVERAGEIF(AM:AM,">0"),AM8) -> 7.7 | Y8: =IF(AN8<0,AVERAGEIF(AN:AN,">0"),AN8) -> 191.8 | Z8: {=INDEX(municipality_wind_potential!$X:$X,MATCH(municipalities!$F8,municipality_wind_potential!$E:$E,0),0)} -> 23 | AA8: =Z8*$AH$2 -> 128.8 | AB8: {=INDEX(municipality_wind_potential!$Y:$Y,MATCH(municipalities!$F8,municipality_wind_potential!$E:$E,0),0) / 3.6} -> 495.88056 | AC8: =AD8/$AH$3*1000 -> 13.134749 | AD8: {=INDEX(municipality_pv_potential!$G:$G,MATCH(municipalities!$A8,municipality_pv_potential!$E:$E,0),0)/3.6*$AH$4} -> 12.162778 | AE8: =AF8/$AH$3*1000 -> 94.867411 | AF8: {=INDEX(municipality_pv_potential!$H:$H,MATCH(municipalities!$A8,municipality_pv_potential!$E:$E,0),0)/3.6} -> 87.847222 | AJ8: -99999 | AK8: 3.9 | AL8: 5.7 | AM8: 7.7 | AN8: 191.8
A9: GM0072 | B9: 0072 | C9: Harlingen | D9: Harlingen | E9: Gemeente | F9: GM0072 | G9: {=INDEX('municipalities per province'!F:F,MATCH(municipalities!A9,'municipalities per province'!B:B,0),0)} -> Friesland | H9: {=INDEX('municipalities per province'!E:E,MATCH(municipalities!$A9,'municipalities per province'!$B:$B,0),0)} -> PV21 | I9: {=INDEX('municipalities per province'!G:G,MATCH(municipalities!$A9,'municipalities per province'!$B:$B,0),0)} -> Friesland | J9: {=INDEX('municipalities per province'!H:H,MATCH(municipalities!$A9,'municipalities per province'!$B:$B,0),0)} -> ES02 | K9: {=INDEX(coordinates!C:C,MATCH(municipalities!$A9,coordinates!$A:$A,0),0)} -> 5.2545118 | L9: {=INDEX(coordinates!D:D,MATCH(municipalities!$A9,coordinates!$A:$A,0),0)} -> 53.140828 | M9: 1 | N9: 16188 | O9: 8115 | P9: 8073 | Q9: 3 | R9: 1092 | S9: 56 | T9: 44 | U9: =IF(AJ9<0,AVERAGEIF(AJ:AJ,">0"),AJ9) -> 29.5 | V9: =IF(AK9<0,AVERAGEIF(AK:AK,">0"),AK9) -> 8.7 | W9: =IF(AL9<0,AVERAGEIF(AL:AL,">0"),AL9) -> 13.1 | X9: =IF(AM9<0,AVERAGEIF(AM:AM,">0"),AM9) -> 16.9 | Y9: =IF(AN9<0,AVERAGEIF(AN:AN,">0"),AN9) -> 51 | Z9: {=INDEX(municipality_wind_potential!$X:$X,MATCH(municipalities!$F9,municipality_wind_potential!$E:$E,0),0)} -> 10 | AA9: =Z9*$AH$2 -> 56 | AB9: {=INDEX(municipality_wind_potential!$Y:$Y,MATCH(municipalities!$F9,municipality_wind_potential!$E:$E,0),0) / 3.6} -> 215.6 | AC9: =AD9/$AH$3*1000 -> 28.512719 | AD9: {=INDEX(municipality_pv_potential!$G:$G,MATCH(municipalities!$A9,municipality_pv_potential!$E:$E,0),0)/3.6*$AH$4} -> 26.402778 | AE9: =AF9/$AH$3*1000 -> 80.939525 | AF9: {=INDEX(municipality_pv_potential!$H:$H,MATCH(municipalities!$A9,municipality_pv_potential!$E:$E,0),0)/3.6} -> 74.95 | AJ9: 29.5 | AK9: 8.7 | AL9: 13.1 | AM9: 16.9 | AN9: 51
A10: GM0074 | B10: 0074 | C10: Heerenveen | D10: Heerenveen | E10: Gemeente | F10: GM0074 | G10: {=INDEX('municipalities per province'!F:F,MATCH(municipalities!A10,'municipalities per province'!B:B,0),0)} -> Friesland | H10: {=INDEX('municipalities per province'!E:E,MATCH(municipalities!$A10,'municipalities per province'!$B:$B,0),0)} -> PV21 | I10: {=INDEX('municipalities per province'!G:G,MATCH(municipalities!$A10,'municipalities per province'!$B:$B,0),0)} -> Friesland | J10: {=INDEX('municipalities per province'!H:H,MATCH(municipalities!$A10,'municipalities per province'!$B:$B,0),0)} -> ES02 | K10: {=INDEX(coordinates!C:C,MATCH(municipalities!$A10,coordinates!$A:$A,0),0)} -> 5.9779107 | L10: {=INDEX(coordinates!D:D,MATCH(municipalities!$A10,coordinates!$A:$A,0),0)} -> 52.995987 | M10: 1 | N10: 51637 | O10: 25706 | P10: 25931 | Q10: 3 | R10: 1109 | S10: 60 | T10: 40 | U10: =IF(AJ10<0,AVERAGEIF(AJ:AJ,">0"),AJ10) -> 32.2 | V10: =IF(AK10<0,AVERAGEIF(AK:AK,">0"),AK10) -> 6.4 | W10: =IF(AL10<0,AVERAGEIF(AL:AL,">0"),AL10) -> 10 | X10: =IF(AM10<0,AVERAGEIF(AM:AM,">0"),AM10) -> 13.1 | Y10: =IF(AN10<0,AVERAGEIF(AN:AN,">0"),AN10) -> 90.9 | Z10: {=INDEX(municipality_wind_potential!$X:$X,MATCH(municipalities!$F10,municipality_wind_potential!$E:$E,0),0)} -> 117 | AA10: =Z10*$AH$2 -> 655.2 | AB10: {=INDEX(municipality_wind_potential!$Y:$Y,MATCH(municipalities!$F10,municipality_wind_potential!$E:$E,0),0) / 3.6} -> 2283.4 | AC10: =AD10/$AH$3*1000 -> 121.87305 | AD10: {=INDEX(municipality_pv_potential!$G:$G,MATCH(municipalities!$A10,municipality_pv_potential!$E:$E,0),0)/3.6*$AH$4} -> 112.85444 | AE10: =AF10/$AH$3*1000 -> 645.12839 | AF10: {=INDEX(municipality_pv_potential!$H:$H,MATCH(municipalities!$A10,municipality_pv_potential!$E:$E,0),0)/3.6} -> 597.38889 | AJ10: 32.2 | AK10: 6.4 | AL10: 10 | AM10: 13.1 | AN10: 90.9
A11: GM0080 | B11: 0080 | C11: Leeuwarden | D11: Leeuwarden | E11: Gemeente | F11: GM0080 | G11: {=INDEX('municipalities per province'!F:F,MATCH(municipalities!A11,'municipalities per province'!B:B,0),0)} -> Friesland | H11: {=INDEX('municipalities per province'!E:E,MATCH(municipalities!$A11,'municipalities per province'!$B:$B,0),0)} -> PV21 | I11: {=INDEX('municipalities per province'!G:G,MATCH(municipalities!$A11,'municipalities per province'!$B:$B,0),0)} -> Friesland | J11: {=INDEX('municipalities per province'!H:H,MATCH(municipalities!$A11,'municipalities per province'!$B:$B,0),0)} -> ES02 | K11: {=INDEX(coordinates!C:C,MATCH(municipalities!$A11,coordinates!$A:$A,0),0)} -> 5.7978953 | L11: {=INDEX(coordinates!D:D,MATCH(municipalities!$A11,coordinates!$A:$A,0),0)} -> 53.170076 | M11: 1 | N11: 127073 | O11: 63248 | P11: 63825 | Q11: 2 | R11: 2196 | S11: 51 | T11: 49 | U11: =IF(AJ11<0,AVERAGEIF(AJ:AJ,">0"),AJ11) -> 28.5 | V11: =IF(AK11<0,AVERAGEIF(AK:AK,">0"),AK11) -> 9.5 | W11: =IF(AL11<0,AVERAGEIF(AL:AL,">0"),AL11) -> 13.9 | X11: =IF(AM11<0,AVERAGEIF(AM:AM,">0"),AM11) -> 16.8 | Y11: =IF(AN11<0,AVERAGEIF(AN:AN,">0"),AN11) -> 36 | Z11: {=INDEX(municipality_wind_potential!$X:$X,MATCH(municipalities!$F11,municipality_wind_potential!$E:$E,0),0)} -> 88 | AA11: =Z11*$AH$2 -> 492.8 | AB11: {=INDEX(municipality_wind_potential!$Y:$Y,MATCH(municipalities!$F11,municipality_wind_potential!$E:$E,0),0) / 3.6} -> 1724.8 | AC11: =AD11/$AH$3*1000 -> 203.16715 | AD11: {=INDEX(municipality_pv_potential!$G:$G,MATCH(municipalities!$A11,municipality_pv_potential!$E:$E,0),0)/3.6*$AH$4} -> 188.13278 | AE11: =AF11/$AH$3*1000 -> 857.4814 | AF11: {=INDEX(municipality_pv_potential!$H:$H,MATCH(municipalities!$A11,municipality_pv_potential!$E:$E,0),0)/3.6} -> 794.02778 | AJ11: 28.5 | AK11: 9.5 | AL11: 13.9 | AM11: 16.8 | AN11: 36
A12: GM0085 | B12: 0085 | C12: Ooststellingwerf | D12: Ooststellingwerf | E12: Gemeente | F12: GM0085 | G12: {=INDEX('municipalities per province'!F:F,MATCH(municipalities!A12,'municipalities per province'!B:B,0),0)} -> Friesland | H12: {=INDEX('municipalities per province'!E:E,MATCH(municipalities!$A12,'municipalities per province'!$B:$B,0),0)} -> PV21 | I12: {=INDEX('municipalities per province'!G:G,MATCH(municipalities!$A12,'municipalities per province'!$B:$B,0),0)} -> Friesland | J12: {=INDEX('municipalities per province'!H:H,MATCH(municipalities!$A12,'municipalities per province'!$B:$B,0),0)} -> ES02 | K12: {=INDEX(coordinates!C:C,MATCH(municipalities!$A12,coordinates!$A:$A,0),0)} -> 6.2829985 | L12: {=INDEX(coordinates!D:D,MATCH(municipalities!$A12,coordinates!$A:$A,0),0)} -> 52.982381 | M12: 1 | N12: 25837 | O12: 12925 | P12: 12912 | Q12: 5 | R12: 482 | S12: 67 | T12: 33 | U12: =IF(AJ12<0,AVERAGEIF(AJ:AJ,">0"),AJ12) -> 31.1 | V12: =IF(AK12<0,AVERAGEIF(AK:AK,">0"),AK12) -> 6.3 | W12: =IF(AL12<0,AVERAGEIF(AL:AL,">0"),AL12) -> 10.1 | X12: =IF(AM12<0,AVERAGEIF(AM:AM,">0"),AM12) -> 12.7 | Y12: =IF(AN12<0,AVERAGEIF(AN:AN,">0"),AN12) -> 120.8 | Z12: {=INDEX(municipality_wind_potential!$X:$X,MATCH(municipalities!$F12,municipality_wind_potential!$E:$E,0),0)} -> 163 | AA12: =Z12*$AH$2 -> 912.8 | AB12: {=INDEX(municipality_wind_potential!$Y:$Y,MATCH(municipalities!$F12,municipality_wind_potential!$E:$E,0),0) / 3.6} -> 2884.7 | AC12: =AD12/$AH$3*1000 -> 87.603192 | AD12: {=INDEX(municipality_pv_potential!$G:$G,MATCH(municipalities!$A12,municipality_pv_potential!$E:$E,0),0)/3.6*$AH$4} -> 81.120556 | AE12: =AF12/$AH$3*1000 -> 699.62803 | AF12: {=INDEX(municipality_pv_potential!$H:$H,MATCH(municipalities!$A12,municipality_pv_potential!$E:$E,0),0)/3.6} -> 647.85556 | AJ12: 31.1 | AK12: 6.3 | AL12: 10.1 | AM12: 12.7 | AN12: 120.8
A13: GM0086 | B13: 0086 | C13: Opsterland | D13: Opsterland | E13: Gemeente | F13: GM0086 | G13: {=INDEX('municipalities per province'!F:F,MATCH(municipalities!A13,'municipalities per province'!B:B,0),0)} -> Friesland | H13: {=INDEX('municipalities per province'!E:E,MATCH(municipalities!$A13,'municipalities per province'!$B:$B,0),0)} -> PV21 | I13: {=INDEX('municipalities per province'!G:G,MATCH(municipalities!$A13,'municipalities per province'!$B:$B,0),0)} -> Friesland | J13: {=INDEX('municipalities per province'!H:H,MATCH(municipalities!$A13,'municipalities per province'!$B:$B,0),0)} -> ES02 | K13: {=INDEX(coordinates!C:C,MATCH(municipalities!$A13,coordinates!$A:$A,0),0)} -> 6.1128479 | L13: {=INDEX(coordinates!D:D,MATCH(municipalities!$A13,coordinates!$A:$A,0),0)} -> 53.049142 | M13: 1 | N13: 30054 | O13: 15092 | P13: 14962 | Q13: 5 | R13: 422 | S13: 70 | T13: 30 | U13: =IF(AJ13<0,AVERAGEIF(AJ:AJ,">0"),AJ13) -> 32.8 | V13: =IF(AK13<0,AVERAGEIF(AK:AK,">0"),AK13) -> 5 | W13: =IF(AL13<0,AVERAGEIF(AL:AL,">0"),AL13) -> 8.1 | X13: =IF(AM13<0,AVERAGEIF(AM:AM,">0"),AM13) -> 10.7 | Y13: =IF(AN13<0,AVERAGEIF(AN:AN,">0"),AN13) -> 151.2 | Z13: {=INDEX(municipality_wind_potential!$X:$X,MATCH(municipalities!$F13,municipality_wind_potential!$E:$E,0),0)} -> 142 | AA13: =Z13*$AH$2 -> 795.2 | AB13: {=INDEX(municipality_wind_potential!$Y:$Y,MATCH(municipalities!$F13,municipality_wind_potential!$E:$E,0),0) / 3.6} -> 2773.4 | AC13: =AD13/$AH$3*1000 -> 90.142189 | AD13: {=INDEX(municipality_pv_potential!$G:$G,MATCH(municipalities!$A13,municipality_pv_potential!$E:$E,0),0)/3.6*$AH$4} -> 83.471667 | AE13: =AF13/$AH$3*1000 -> 784.58423 | AF13: {=INDEX(municipality_pv_potential!$H:$H,MATCH(municipalities!$A13,municipality_pv_potential!$E:$E,0),0)/3.6} -> 726.525 | AJ13: 32.8 | AK13: 5 | AL13: 8.1 | AM13: 10.7 | AN13: 151.2
A14: GM0088 | B14: 0088 | C14: Schiermonnikoog | D14: Schiermonnikoog | E14: Gemeente | F14: GM0088 | G14: {=INDEX('municipalities per province'!F:F,MATCH(municipalities!A14,'municipalities per province'!B:B,0),0)} -> Friesland | H14: {=INDEX('municipalities per province'!E:E,MATCH(municipalities!$A14,'municipalities per province'!$B:$B,0),0)} -> PV21 | I14: {=INDEX('municipalities per province'!G:G,MATCH(municipalities!$A14,'municipalities per province'!$B:$B,0),0)} -> Friesland | J14: {=INDEX('municipalities per province'!H:H,MATCH(municipalities!$A14,'municipalities per province'!$B:$B,0),0)} -> ES02 | K14: {=INDEX(coordinates!C:C,MATCH(municipalities!$A14,coordinates!$A:$A,0),0)} -> 6.2211923 | L14: {=INDEX(coordinates!D:D,MATCH(municipalities!$A14,coordinates!$A:$A,0),0)} -> 53.469887 | M14: 1 | N14: 982 | O14: 519 | P14: 463 | Q14: 5 | R14: 325 | S14: 53 | T14: 46 | U14: =IF(AJ14<0,AVERAGEIF(AJ:AJ,">0"),AJ14) -> 34.730631 | V14: =IF(AK14<0,AVERAGEIF(AK:AK,">0"),AK14) -> 4.7 | W14: =IF(AL14<0,AVERAGEIF(AL:AL,">0"),AL14) -> 8.4 | X14: =IF(AM14<0,AVERAGEIF(AM:AM,">0"),AM14) -> 10.5 | Y14: =IF(AN14<0,AVERAGEIF(AN:AN,">0"),AN14) -> 123.1 | Z14: {=INDEX(municipality_wind_potential!$X:$X,MATCH(municipalities!$F14,municipality_wind_potential!$E:$E,0),0)} -> 12 | AA14: =Z14*$AH$2 -> 67.2 | AB14: {=INDEX(municipality_wind_potential!$Y:$Y,MATCH(municipalities!$F14,municipality_wind_potential!$E:$E,0),0) / 3.6} -> 247.93889 | AC14: =AD14/$AH$3*1000 -> 3.174946 | AD14: {=INDEX(municipality_pv_potential!$G:$G,MATCH(municipalities!$A14,municipality_pv_potential!$E:$E,0),0)/3.6*$AH$4} -> 2.94 | AE14: =AF14/$AH$3*1000 -> 30.042597 | AF14: {=INDEX(municipality_pv_potential!$H:$H,MATCH(municipalities!$A14,municipality_pv_potential!$E:$E,0),0)/3.6} -> 27.819444 | AJ14: -99999 | AK14: 4.7 | AL14: 8.4 | AM14: 10.5 | AN14: 123.1
A15: GM0090 | B15: 0090 | C15: Smallingerland | D15: Smallingerland | E15: Gemeente | F15: GM0090 | G15: {=INDEX('municipalities per province'!F:F,MATCH(municipalities!A15,'municipalities per province'!B:B,0),0)} -> Friesland | H15: {=INDEX('municipalities per province'!E:E,MATCH(municipalities!$A15,'municipalities per province'!$B:$B,0),0)} -> PV21 | I15: {=INDEX('municipalities per province'!G:G,MATCH(municipalities!$A15,'municipalities per province'!$B:$B,0),0)} -> Friesland | J15: {=INDEX('municipalities per province'!H:H,MATCH(municipalities!$A15,'municipalities per province'!$B:$B,0),0)} -> ES02 | K15: {=INDEX(coordinates!C:C,MATCH(municipalities!$A15,coordinates!$A:$A,0),0)} -> 6.0389611 | L15: {=INDEX(coordinates!D:D,MATCH(municipalities!$A15,coordinates!$A:$A,0),0)} -> 53.113412 | M15: 1 | N15: 56098 | O15: 27963 | P15: 28135 | Q15: 3 | R15: 1342 | S15: 60 | T15: 40 | U15: =IF(AJ15<0,AVERAGEIF(AJ:AJ,">0"),AJ15) -> 30.4 | V15: =IF(AK15<0,AVERAGEIF(AK:AK,">0"),AK15) -> 7.1 | W15: =IF(AL15<0,AVERAGEIF(AL:AL,">0"),AL15) -> 11.7 | X15: =IF(AM15<0,AVERAGEIF(AM:AM,">0"),AM15) -> 14.8 | Y15: =IF(AN15<0,AVERAGEIF(AN:AN,">0"),AN15) -> 70.7 | Z15: {=INDEX(municipality_wind_potential!$X:$X,MATCH(municipalities!$F15,municipality_wind_potential!$E:$E,0),0)} -> 47 | AA15: =Z15*$AH$2 -> 263.2 | AB15: {=INDEX(municipality_wind_potential!$Y:$Y,MATCH(municipalities!$F15,municipality_wind_potential!$E:$E,0),0) / 3.6} -> 921.2 | AC15: =AD15/$AH$3*1000 -> 108.6909 | AD15: {=INDEX(municipality_pv_potential!$G:$G,MATCH(municipalities!$A15,municipality_pv_potential!$E:$E,0),0)/3.6*$AH$4} -> 100.64778 | AE15: =AF15/$AH$3*1000 -> 388.15095 | AF15: {=INDEX(municipality_pv_potential!$H:$H,MATCH(municipalities!$A15,municipality_pv_potential!$E:$E,0),0)/3.6} -> 359.42778 | AJ15: 30.4 | AK15: 7.1 | AL15: 11.7 | AM15: 14.8 | AN15: 70.7
A16: GM0093 | B16: 0093 | C16: Terschelling | D16: Terschelling | E16: Gemeente | F16: GM0093 | G16: {=INDEX('municipalities per province'!F:F,MATCH(municipalities!A16,'municipalities per province'!B:B,0),0)} -> Friesland | H16: {=INDEX('municipalities per province'!E:E,MATCH(municipalities!$A16,'municipalities per province'!$B:$B,0),0)} -> PV21 | I16: {=INDEX('municipalities per province'!G:G,MATCH(municipalities!$A16,'municipalities per province'!$B:$B,0),0)} -> Friesland | J16: {=INDEX('municipalities per province'!H:H,MATCH(municipalities!$A16,'municipalities per province'!$B:$B,0),0)} -> ES02 | K16: {=INDEX(coordinates!C:C,MATCH(municipalities!$A16,coordinates!$A:$A,0),0)} -> 5.3817025 | L16: {=INDEX(coordinates!D:D,MATCH(municipalities!$A16,coordinates!$A:$A,0),0)} -> 53.331216 | M16: 1 | N16: 4928 | O16: 2497 | P16: 2431 | Q16: 5 | R16: 254 | S16: 63 | T16: 37 | U16: =IF(AJ16<0,AVERAGEIF(AJ:AJ,">0"),AJ16) -> 32.7 | V16: =IF(AK16<0,AVERAGEIF(AK:AK,">0"),AK16) -> 3.5 | W16: =IF(AL16<0,AVERAGEIF(AL:AL,">0"),AL16) -> 5.2 | X16: =IF(AM16<0,AVERAGEIF(AM:AM,">0"),AM16) -> 7.6 | Y16: =IF(AN16<0,AVERAGEIF(AN:AN,">0"),AN16) -> 160.7 | Z16: {=INDEX(municipality_wind_potential!$X:$X,MATCH(municipalities!$F16,municipality_wind_potential!$E:$E,0),0)} -> 64 | AA16: =Z16*$AH$2 -> 358.4 | AB16: {=INDEX(municipality_wind_potential!$Y:$Y,MATCH(municipalities!$F16,municipality_wind_potential!$E:$E,0),0) / 3.6} -> 1379.8389 | AC16: =AD16/$AH$3*1000 -> 12.460403 | AD16: {=INDEX(municipality_pv_potential!$G:$G,MATCH(municipalities!$A16,municipality_pv_potential!$E:$E,0),0)/3.6*$AH$4} -> 11.538333 | AE16: =AF16/$AH$3*1000 -> 65.991721 | AF16: {=INDEX(municipality_pv_potential!$H:$H,MATCH(municipalities!$A16,municipality_pv_potential!$E:$E,0),0)/3.6} -> 61.108333 | AJ16: 32.7 | AK16: 3.5 | AL16: 5.2 | AM16: 7.6 | AN16: 160.7
... A343: GM1992 | B343: 1992 | C343: Voorne aan Zee | D343: Voorne aan Zee | E343: Gemeente | F343: GM1992 | G343: {=INDEX('municipalities per province'!F:F,MATCH(municipalities!A343,'municipalities per province'!B:B,0),0)} -> Zuid-Holland | H343: {=INDEX('municipalities per province'!E:E,MATCH(municipalities!$A343,'municipalities per province'!$B:$B,0),0)} -> PV28 | I343: {=INDEX('municipalities per province'!G:G,MATCH(municipalities!$A343,'municipalities per province'!$B:$B,0),0)} -> Rotterdam/DenHaag | J343: {=INDEX('municipalities per province'!H:H,MATCH(municipalities!$A343,'municipalities per province'!$B:$B,0),0)} -> ES23 | K343: {=INDEX(coordinates!C:C,MATCH(municipalities!$A343,coordinates!$A:$A,0),0)} -> 4.0453245 | L343: {=INDEX(coordinates!D:D,MATCH(municipalities!$A343,coordinates!$A:$A,0),0)} -> 51.862241 | M343: 3 | N343: 73945 | O343: 36582 | P343: 37363 | Q343: 3 | R343: 1182 | S343: 67 | T343: 33 | U343: =IF(AJ343<0,AVERAGEIF(AJ:AJ,">0"),AJ343) -> 34.730631 | V343: =IF(AK343<0,AVERAGEIF(AK:AK,">0"),AK343) -> 5.0195266 | W343: =IF(AL343<0,AVERAGEIF(AL:AL,">0"),AL343) -> 7.8180473 | X343: =IF(AM343<0,AVERAGEIF(AM:AM,">0"),AM343) -> 10.309172 | Y343: =IF(AN343<0,AVERAGEIF(AN:AN,">0"),AN343) -> 147.2568 | Z343: {=INDEX(municipality_wind_potential!$X:$X,MATCH(municipalities!$F343,municipality_wind_potential!$E:$E,0),0)} -> 50 | AA343: =Z343*$AH$2 -> 280 | AB343: {=INDEX(municipality_wind_potential!$Y:$Y,MATCH(municipalities!$F343,municipality_wind_potential!$E:$E,0),0) / 3.6} -> 930.10278 | AC343: =AD343/$AH$3*1000 -> 102.16463 | AD343: {=INDEX(municipality_pv_potential!$G:$G,MATCH(municipalities!$A343,municipality_pv_potential!$E:$E,0),0)/3.6*$AH$4} -> 94.604444 | AE343: =AF343/$AH$3*1000 -> 283.12035 | AF343: {=INDEX(municipality_pv_potential!$H:$H,MATCH(municipalities!$A343,municipality_pv_potential!$E:$E,0),0)/3.6} -> 262.16944 | AJ343: -99999 | AK343: -99999 | AL343: -99999 | AM343: -99999 | AN343: -99999

Sheet municipality_pv_potential
A1: fid | B1: OBJECTID | C1: gid | D1: id | E1: gem_code | F1: gem_naam | G1: tj_dak | H1: tj_lbg_4 | I1: tj_lbg_10 | J1: tj_lbg_100 | K1: tj_wat | L1: tj_tot_pot | M1: gwh_pot | N1: kans2030 | O1: SHAPE_Length | P1: SHAPE_Area | Q1: cbs_rescode
A2: 1 | B2: 1 | C2: 1 | D2: 18 | E2: GM0074 | F2: Heerenveen | G2: 2031.38 | H2: 2150.6 | I2: 5376.5 | J2: 53765 | K2: 0.06 | L2: 4182.04 | M2: 1161.77 | N2: Kansrijk | O2: 102967.39 | P2: 1.981691e+08 | Q2: ES02
A3: 2 | B3: 2 | C3: 2 | D3: 19 | E3: GM0080 | F3: Leeuwarden | G3: 3386.39 | H3: 2858.5 | I3: 7146.26 | J3: 71462.61 | K3: 29.45 | L3: 6274.34 | M3: 1743.01 | N3: Kansrijk | O3: 126325.71 | P3: 2.5571769e+08 | Q3: ES02
A4: 3 | B4: 3 | C4: 3 | D4: 20 | E4: GM0118 | F4: Hoogeveen | G4: 1992.22 | H4: 1189.92 | I4: 2974.81 | J4: 29748.1 | K4: 0 | L4: 3182.14 | M4: 884 | N4: Kansrijk | O4: 64898.134 | P4: 1.2922166e+08 | Q4: ES03
A5: 4 | B5: 4 | C5: 4 | D5: 21 | E5: GM0119 | F5: Meppel | G5: 1029.74 | H5: 578.68 | I5: 1446.71 | J5: 14467.11 | K5: 0 | L5: 1608.42 | M5: 446.82 | N5: Kansrijk | O5: 53026.576 | P5: 56984399 | Q5: ES03
A6: 5 | B6: 5 | C6: 5 | D6: 25 | E6: GM0086 | F6: Opsterland | G6: 1502.49 | H6: 2615.49 | I6: 6538.74 | J6: 65387.37 | K6: 0 | L6: 4117.98 | M6: 1143.97 | N6: Kansrijk | O6: 84906.696 | P6: 2.2768263e+08 | Q6: ES02
A7: 6 | B7: 6 | C7: 6 | D7: 26 | E7: GM0088 | F7: Schiermonnikoog | G7: 52.92 | H7: 100.15 | I7: 250.38 | J7: 2503.76 | K7: 0 | L7: 153.07 | M7: 42.52 | N7: Kansrijk | O7: 39179.769 | P7: 41456527 | Q7: ES02
A8: 7 | B8: 7 | C8: 7 | D8: 31 | E8: GM0148 | F8: Dalfsen | G8: 1704.55 | H8: 1962.99 | I8: 4907.48 | J8: 49074.83 | K8: 0 | L8: 3667.54 | M8: 1018.84 | N8: Kansrijk | O8: 70836.038 | P8: 1.6650166e+08 | Q8: ES05
A9: 8 | B9: 8 | C9: 8 | D9: 41 | E9: GM0160 | F9: Hardenberg | G9: 3127.92 | H9: 3752.86 | I9: 9382.14 | J9: 93821.4 | K9: 0 | L9: 6880.78 | M9: 1911.48 | N9: Kansrijk | O9: 122593.31 | P9: 3.1724463e+08 | Q9: ES05
A10: 9 | B10: 9 | C10: 9 | D10: 42 | E10: GM0163 | F10: Hellendoorn | G10: 1513.96 | H10: 1104.99 | I10: 2762.47 | J10: 27624.73 | K10: 0 | L10: 2618.95 | M10: 727.54 | N10: Kansrijk | O10: 67252.731 | P10: 1.3902498e+08 | Q10: ES04
A11: 10 | B11: 10 | C11: 10 | D11: 44 | E11: GM1699 | F11: Noordenveld | G11: 1300.41 | H11: 1756.56 | I11: 4391.4 | J11: 43914.04 | K11: 0 | L11: 3056.97 | M11: 849.23 | N11: Kansrijk | O11: 74562.973 | P11: 2.0532923e+08 | Q11: ES03
A12: 11 | B12: 11 | C12: 11 | D12: 45 | E12: GM1700 | F12: Twenterand | G12: 1390.39 | H12: 1101.23 | I12: 2753.09 | J12: 27530.85 | K12: 0 | L12: 2491.62 | M12: 692.17 | N12: Kansrijk | O12: 72130.348 | P12: 1.0816676e+08 | Q12: ES04
A13: 12 | B13: 12 | C13: 12 | D13: 46 | E13: GM1701 | F13: Westerveld | G13: 1055.11 | H13: 2007.97 | I13: 5019.91 | J13: 50199.14 | K13: 0 | L13: 3063.08 | M13: 850.92 | N13: Kansrijk | O13: 98147.562 | P13: 2.8274732e+08 | Q13: ES03
... A356: 355 | B356: 355 | C356: 355 | D356: 351 | E356: GM1963 | F356: Hoeksche Waard | G356: 2571.33 | H356: 3419.33 | I356: 8548.33 | J356: 85483.31 | K356: 0 | L356: 5990.66 | M356: 1664.21 | N356: Kansrijk | O356: 89947.302 | P356: 2.8314147e+08 | Q356: ES20
A357: 1001 | B357: 1001 | C357: 1001 | D357: 1001 | E357: GM1979 | F357: Eemsdelta | G357: {=SUM(SUMIFS(G$2:G$356, $E$2:$E$356, $S$358:$S$360))} -> 2099.99 | H357: {=SUM(SUMIFS(H$2:H$356, $E$2:$E$356, $S$358:$S$360))} -> 3611.69 | I357: {=SUM(SUMIFS(I$2:I$356, $E$2:$E$356, $S$358:$S$360))} -> 9029.24 | J357: {=SUM(SUMIFS(J$2:J$356, $E$2:$E$356, $S$358:$S$360))} -> 90292.32 | K357: {=SUM(SUMIFS(K$2:K$356, $E$2:$E$356, $S$358:$S$360))} -> 0.35 | L357: {=SUM(SUMIFS(L$2:L$356, $E$2:$E$356, $S$358:$S$360))} -> 5712.03 | M357: {=SUM(SUMIFS(M$2:M$356, $E$2:$E$356, $S$358:$S$360))} -> 1586.8 | O357: {=SUM(SUMIFS(O$2:O$356, $E$2:$E$356, $S$358:$S$360))} -> 178064.65 | P357: {=SUM(SUMIFS(P$2:P$356, $E$2:$E$356, $S$358:$S$360))} -> 2.7228554e+08 | S357: GM1979 | T357: Eemsdelta | X357: GM1979
A358: 1002 | B358: 1002 | C358: 1002 | D358: 1002 | E358: GM1980 | F358: Dijk en Waard | G358: {=SUM(SUMIFS(G$2:G$356, $E$2:$E$356, $S$362:$S$364))} -> 2062 | H358: {=SUM(SUMIFS(H$2:H$356, $E$2:$E$356, $S$362:$S$364))} -> 411.39 | I358: {=SUM(SUMIFS(I$2:I$356, $E$2:$E$356, $S$362:$S$364))} -> 1028.45 | J358: {=SUM(SUMIFS(J$2:J$356, $E$2:$E$356, $S$362:$S$364))} -> 10284.53 | K358: {=SUM(SUMIFS(K$2:K$356, $E$2:$E$356, $S$362:$S$364))} -> 11.33 | L358: {=SUM(SUMIFS(L$2:L$356, $E$2:$E$356, $S$362:$S$364))} -> 2484.72 | M358: {=SUM(SUMIFS(M$2:M$356, $E$2:$E$356, $S$362:$S$364))} -> 690.25 | O358: {=SUM(SUMIFS(O$2:O$356, $E$2:$E$356, $S$362:$S$364))} -> 64949.164 | P358: {=SUM(SUMIFS(P$2:P$356, $E$2:$E$356, $S$362:$S$364))} -> 66960166 | S358: GM0003 | V358: Appingedam | X358: GM0003
A359: 1003 | B359: 1003 | C359: 1003 | D359: 1003 | E359: GM1982 | F359: Land van Cuijk | G359: {=SUM(SUMIFS(G$2:G$356, $E$2:$E$356, $S$366:$S$371))} -> 4791.29 | H359: {=SUM(SUMIFS(H$2:H$356, $E$2:$E$356, $S$366:$S$371))} -> 3598.52 | I359: {=SUM(SUMIFS(I$2:I$356, $E$2:$E$356, $S$366:$S$371))} -> 8996.33 | J359: {=SUM(SUMIFS(J$2:J$356, $E$2:$E$356, $S$366:$S$371))} -> 89963.34 | K359: {=SUM(SUMIFS(K$2:K$356, $E$2:$E$356, $S$366:$S$371))} -> 0 | L359: {=SUM(SUMIFS(L$2:L$356, $E$2:$E$356, $S$366:$S$371))} -> 8389.81 | M359: {=SUM(SUMIFS(M$2:M$356, $E$2:$E$356, $S$366:$S$371))} -> 2330.68 | O359: {=SUM(SUMIFS(O$2:O$356, $E$2:$E$356, $S$366:$S$371))} -> 209855.06 | P359: {=SUM(SUMIFS(P$2:P$356, $E$2:$E$356, $S$366:$S$371))} -> 3.5187058e+08 | S359: GM0024 | V359: Loppersum | X359: GM0024
A360: 1004 | B360: 1004 | C360: 1004 | D360: 1004 | E360: GM1991 | F360: Maashorst | G360: {=SUM(SUMIFS(G$2:G$356, $E$2:$E$356, $S$373:$S$375))} -> 2705.77 | H360: {=SUM(SUMIFS(H$2:H$356, $E$2:$E$356, $S$373:$S$375))} -> 1137.3 | I360: {=SUM(SUMIFS(I$2:I$356, $E$2:$E$356, $S$373:$S$375))} -> 2843.24 | J360: {=SUM(SUMIFS(J$2:J$356, $E$2:$E$356, $S$373:$S$375))} -> 28432.45 | K360: {=SUM(SUMIFS(K$2:K$356, $E$2:$E$356, $S$373:$S$375))} -> 0 | L360: {=SUM(SUMIFS(L$2:L$356, $E$2:$E$356, $S$373:$S$375))} -> 3843.07 | M360: {=SUM(SUMIFS(M$2:M$356, $E$2:$E$356, $S$373:$S$375))} -> 1067.61 | O360: {=SUM(SUMIFS(O$2:O$356, $E$2:$E$356, $S$373:$S$375))} -> 91370.954 | P360: {=SUM(SUMIFS(P$2:P$356, $E$2:$E$356, $S$373:$S$375))} -> 1.3827262e+08 | S360: GM0010 | V360: Delfzijl | X360: GM0010
A361: 1005 | B361: 1005 | C361: 1005 | D361: 1005 | E361: GM1992 | F361: Voorne aan Zee | G361: {=SUM(SUMIFS(G$2:G$356, $E$2:$E$356, $S$378:$S$380))} -> 1702.88 | H361: {=SUM(SUMIFS(H$2:H$356, $E$2:$E$356, $S$378:$S$380))} -> 943.81 | I361: {=SUM(SUMIFS(I$2:I$356, $E$2:$E$356, $S$378:$S$380))} -> 2359.54 | J361: {=SUM(SUMIFS(J$2:J$356, $E$2:$E$356, $S$378:$S$380))} -> 23595.38 | K361: {=SUM(SUMIFS(K$2:K$356, $E$2:$E$356, $S$378:$S$380))} -> 0 | L361: {=SUM(SUMIFS(L$2:L$356, $E$2:$E$356, $S$378:$S$380))} -> 2646.69 | M361: {=SUM(SUMIFS(M$2:M$356, $E$2:$E$356, $S$378:$S$380))} -> 735.25 | O361: {=SUM(SUMIFS(O$2:O$356, $E$2:$E$356, $S$378:$S$380))} -> 108361.82 | P361: {=SUM(SUMIFS(P$2:P$356, $E$2:$E$356, $S$378:$S$380))} -> 1.3218336e+08
S362: GM1980 | T362: 1980 | U362: Dijk en Waard | X362: GM1980
S363: GM0398 | T363: Heerhugowaard | X363: GM0398
S364: GM0416 | T364: Langedijk | X364: GM0416
S366: GM1982 | T366: 1982 | U366: Land van Cuijk | X366: GM1982
S367: GM0756 | T367: Boxmeer | X367: GM0756
S368: GM1684 | T368: Cuijk | X368: GM1684
S369: GM1702 | T369: Sint Anthonis | X369: GM1702
S370: GM0815 | T370: Mill en Sint Hubert | X370: GM0815
S371: GM0786 | T371: Grave | X371: GM0786
S373: GM1991 | T373: 1991 | U373: Maashorst | X373: GM1991
S374: GM1685 | T374: Landerd | X374: GM1685
S375: GM0856 | T375: Uden | X375: GM0856
S377: GM1992 | T377: 1992 | U377: Voorne aan Zee | X377: GM1992
S378: GM0501 | T378: Brielle | X378: GM0501
S379: GM0530 | T379: Hellevoetsluis | X379: GM0530
S380: GM0614 | T380: Westvoorne | X380: GM0614

Sheet municipality_wind_potential
A1: fid | B1: OBJECTID | C1: gid | D1: id | E1: gem_code | F1: gem_naam | G1: kw | H1: opp_meer | I1: opp_land | J1: pct_agr | K1: pct_beb | L1: pct_nat | M1: pct_wat | N1: pct_ovr | O1: a_max_mr | P1: tj_max_mr | Q1: cor_fac_mr | R1: a_pot_mr | S1: tj_pot_mr | T1: a_km2_mr | U1: a_max_lnd | V1: tj_max_lnd | W1: cor_fac_ln | X1: a_pot_lnd | Y1: tj_pot_lnd | Z1: a_km2_lnd | AA1: tj_tot | AB1: gwh_tot | AC1: SHAPE_Length | AD1: SHAPE_Area | AE1: cbs_rescode
A2: 1 | B2: 1 | C2: 1 | D2: 453 | E2: GM0301 | F2: Zutphen | G2: 5600 | H2: 0 | I2: 6.64 | J2: 38.86 | K2: 0 | L2: 60.39 | M2: 0.45 | N2: 0.3 | O2: 0 | P2: 0 | Q2: 1 | R2: 0 | S2: 0 | T2: 0 | U2: 16 | V2: 854.78 | W2: 0.5 | X2: 8 | Y2: 427.39 | Z2: 1.2 | AA2: 427.39 | AB2: 118.72 | AC2: 43660.845 | AD2: 42839845 | AE2: ES12
A3: 2 | B3: 2 | C3: 2 | D3: 370 | E3: GM0109 | F3: Coevorden | G3: 5600 | H3: 0 | I3: 201.51 | J3: 68.07 | K3: 0.16 | L3: 30.29 | M3: 1.15 | N3: 0.34 | O3: 0 | P3: 0 | Q3: 1 | R3: 0 | S3: 0 | T3: 0 | U3: 318 | V3: 20322.49 | W3: 0.5 | X3: 159 | Y3: 10161.24 | Z3: 0.79 | AA3: 10161.24 | AB3: 2822.57 | AC3: 88620.436 | AD3: 2.996822e+08 | AE3: ES03
A4: 3 | B4: 3 | C4: 3 | D4: 442 | E4: GM0275 | F4: Rheden | G4: 5600 | H4: 0 | I4: 113.16 | J4: 16.65 | K4: 0.13 | L4: 82.08 | M4: 1.06 | N4: 0.08 | O4: 0 | P4: 0 | Q4: 1 | R4: 0 | S4: 0 | T4: 0 | U4: 133 | V4: 7105.39 | W4: 0.5 | X4: 67 | Y4: 3552.7 | Z4: 0.59 | AA4: 3552.7 | AB4: 986.86 | AC4: 49206.011 | AD4: 84390339 | AE4: ES08
A5: 4 | B5: 4 | C5: 4 | D5: 523 | E5: GM0556 | F5: Maassluis | G5: 5600 | H5: 0 | I5: 0.1 | J5: 30 | K5: 40 | L5: 30 | M5: 0 | N5: 0 | O5: 0 | P5: 0 | Q5: 1 | R5: 0 | S5: 0 | T5: 0 | U5: 0 | V5: 0 | W5: 0.5 | X5: 0 | Y5: 0 | Z5: 0 | AA5: 0 | AB5: 0 | AC5: 15789.775 | AD5: 10110378 | AE5: ES23
A6: 5 | B6: 5 | C6: 5 | D6: 682 | E6: GM1876 | F6: Bronckhorst | G6: 5600 | H6: 0 | I6: 70.82 | J6: 63.32 | K6: 0.28 | L6: 34.17 | M6: 1.37 | N6: 0.86 | O6: 0 | P6: 0 | Q6: 1 | R6: 0 | S6: 0 | T6: 0 | U6: 209 | V6: 11165.62 | W6: 0.5 | X6: 105 | Y6: 5582.81 | Z6: 1.48 | AA6: 5582.81 | AB6: 1550.78 | AC6: 106793.81 | AD6: 2.8641262e+08 | AE6: ES07
A7: 6 | B7: 6 | C7: 6 | D7: 683 | E7: GM1883 | F7: Sittard-Geleen | G7: 5600 | H7: 0 | I7: 18.12 | J7: 74.67 | K7: 4.97 | L7: 15.89 | M7: 4.25 | N7: 0.22 | O7: 0 | P7: 0 | Q7: 1 | R7: 0 | S7: 0 | T7: 0 | U7: 40 | V7: 2136.96 | W7: 0.5 | X7: 20 | Y7: 1068.48 | Z7: 1.1 | AA7: 1068.48 | AB7: 296.8 | AC7: 50070.663 | AD7: 80620955 | AE7: ES30
A8: 7 | B8: 7 | C8: 7 | D8: 384 | E8: GM0184 | F8: Urk | G8: 5600 | H8: 91.1 | I8: 5.3 | J8: 47.36 | K8: 0 | L8: 51.7 | M8: 0.57 | N8: 0.38 | O8: 258 | P8: 21949.4 | Q8: 1 | R8: 258 | S8: 21949.4 | T8: 2.83 | U8: 10 | V8: 705.6 | W8: 0.5 | X8: 5 | Y8: 352.8 | Z8: 0.94 | AA8: 22302.2 | AB8: 6195.06 | AC8: 14638.35 | AD8: 11971771 | AE8: ES06
A9: 8 | B9: 8 | C9: 8 | D9: 697 | E9: GM1940 | F9: De Fryske Marren | G9: 5600 | H9: 156.43 | I9: 338.88 | J9: 80.75 | K9: 0.01 | L9: 11.06 | M9: 7.79 | N9: 0.39 | O9: 437 | P9: 37177.86 | Q9: 1 | R9: 437 | S9: 37177.86 | T9: 2.79 | U9: 517 | V9: 36479.52 | W9: 0.5 | X9: 259 | Y9: 18239.76 | Z9: 0.76 | AA9: 55417.62 | AB9: 15393.8 | AC9: 128733.38 | AD9: 4.1798032e+08 | AE9: ES02
A10: 9 | B10: 9 | C10: 9 | D10: 357 | E10: GM0010 | F10: Delfzijl | G10: 5600 | H10: 75.07 | I10: 77.3 | J10: 85.01 | K10: 0.54 | L10: 12.01 | M10: 1.68 | N10: 0.76 | O10: 220 | P10: 18716.54 | Q10: 1 | R10: 220 | S10: 18716.54 | T10: 2.93 | U10: 141 | V10: 9948.96 | W10: 0.5 | X10: 71 | Y10: 4974.48 | Z10: 0.92 | AA10: 23691.02 | AB10: 6580.84 | AC10: 87605.267 | AD10: 1.3567115e+08 | AE10: ES01
A11: 10 | B11: 10 | C11: 10 | D11: 358 | E11: GM0014 | F11: Groningen | G11: 5600 | H11: 1.12 | I11: 53.78 | J11: 78.28 | K11: 0.22 | L11: 14.63 | M11: 3.07 | N11: 3.79 | O11: 2 | P11: 170.15 | Q11: 1 | R11: 2 | S11: 170.15 | T11: 1.79 | U11: 120 | V11: 8021.46 | W11: 0.5 | X11: 60 | Y11: 4010.73 | Z11: 1.12 | AA11: 4180.88 | AB11: 1161.36 | AC11: 98196.653 | AD11: 1.9785638e+08 | AE11: ES01
A12: 11 | B12: 11 | C12: 11 | D12: 707 | E12: GM1966 | F12: Het Hogeland | G12: 5600 | H12: 93.5 | I12: 421.02 | J12: 79.59 | K12: 0.68 | L12: 18.65 | M12: 0.71 | N12: 0.36 | O12: 286 | P12: 24331.51 | Q12: 1 | R12: 286 | S12: 24331.51 | T12: 3.06 | U12: 672 | V12: 51191.28 | W12: 0.5 | X12: 336 | Y12: 25595.64 | Z12: 0.8 | AA12: 49927.15 | AB12: 13868.66 | AC12: 197812.6 | AD12: 4.7961909e+08 | AE12: ES01
A13: 12 | B13: 12 | C13: 12 | D13: 690 | E13: GM1900 | F13: Sdwest-Frysln | G13: 5600 | H13: 315.26 | I13: 383.57 | J13: 88.18 | K13: 0.02 | L13: 6.19 | M13: 5.61 | N13: 0 | O13: 919 | P13: 78184.11 | Q13: 1 | R13: 919 | S13: 78184.11 | T13: 2.92 | U13: 676 | V13: 52468.42 | W13: 0.5 | X13: 338 | Y13: 26234.21 | Z13: 0.88 | AA13: 104418.32 | AB13: 29005.11 | AC13: 191138.95 | AD13: 5.7498118e+08 | AE13: ES02
... A356: 355 | B356: 355 | C356: 355 | D356: 706 | E356: GM1963 | F356: Hoeksche Waard | G356: 5600 | H356: 0.37 | I356: 210.99 | J356: 79.12 | K356: 0.03 | L356: 16.83 | M356: 3.1 | N356: 0.92 | O356: 9 | P356: 765.68 | Q356: 1 | R356: 9 | S356: 765.68 | T356: 24.32 | U356: 364 | V356: 23262.22 | W356: 0.5 | X356: 182 | Y356: 11631.11 | Z356: 0.86 | AA356: 12396.79 | AB356: 3443.56 | AC356: 89947.302 | AD356: 2.8314147e+08 | AE356: ES20
A357: 1001 | B357: 1001 | C357: 1001 | D357: 1001 | E357: GM1979 | F357: Eemsdelta | G357: {=SUM(SUMIFS(G$2:G$356, $E$2:$E$356, $B$365:$B$367))} -> 16800 | H357: {=SUM(SUMIFS(H$2:H$356, $E$2:$E$356, $B$365:$B$367))} -> 75.07 | I357: {=SUM(SUMIFS(I$2:I$356, $E$2:$E$356, $B$365:$B$367))} -> 141.74 | J357: {=SUM(SUMIFS(J$2:J$356, $E$2:$E$356, $B$365:$B$367))} -> 275.96 | K357: {=SUM(SUMIFS(K$2:K$356, $E$2:$E$356, $B$365:$B$367))} -> 0.54 | L357: {=SUM(SUMIFS(L$2:L$356, $E$2:$E$356, $B$365:$B$367))} -> 18.69 | M357: {=SUM(SUMIFS(M$2:M$356, $E$2:$E$356, $B$365:$B$367))} -> 4.01 | O357: {=SUM(SUMIFS(O$2:O$356, $E$2:$E$356, $B$365:$B$367))} -> 220 | P357: {=SUM(SUMIFS(P$2:P$356, $E$2:$E$356, $B$365:$B$367))} -> 18716.54 | R357: {=SUM(SUMIFS(R$2:R$356, $E$2:$E$356, $B$365:$B$367))} -> 220 | S357: {=SUM(SUMIFS(S$2:S$356, $E$2:$E$356, $B$365:$B$367))} -> 18716.54 | T357: {=SUM(SUMIFS(T$2:T$356, $E$2:$E$356, $B$365:$B$367))} -> 2.93 | U357: {=SUM(SUMIFS(U$2:U$356, $E$2:$E$356, $B$365:$B$367))} -> 289 | V357: {=SUM(SUMIFS(V$2:V$356, $E$2:$E$356, $B$365:$B$367))} -> 20391.84 | X357: {=SUM(SUMIFS(X$2:X$356, $E$2:$E$356, $B$365:$B$367))} -> 145 | Y357: {=SUM(SUMIFS(Y$2:Y$356, $E$2:$E$356, $B$365:$B$367))} -> 10195.92 | Z357: {=SUM(SUMIFS(Z$2:Z$356, $E$2:$E$356, $B$365:$B$367))} -> 4.48 | AA357: {=SUM(SUMIFS(AA$2:AA$356, $E$2:$E$356, $B$365:$B$367))} -> 28912.46 | AB357: {=SUM(SUMIFS(AB$2:AB$356, $E$2:$E$356, $B$365:$B$367))} -> 8031.24 | AC357: {=SUM(SUMIFS(AC$2:AC$356, $E$2:$E$356, $B$365:$B$367))} -> 178064.65 | AD357: {=SUM(SUMIFS(AD$2:AD$356, $E$2:$E$356, $B$365:$B$367))} -> 2.7228554e+08
A358: 1002 | B358: 1002 | C358: 1002 | D358: 1002 | E358: GM1980 | F358: Dijk en Waard | G358: {=SUM(SUMIFS(G$2:G$356, $E$2:$E$356, $B$369:$B$371))} -> 11200 | H358: {=SUM(SUMIFS(H$2:H$356, $E$2:$E$356, $B$369:$B$371))} -> 0 | I358: {=SUM(SUMIFS(I$2:I$356, $E$2:$E$356, $B$369:$B$371))} -> 8.16 | J358: {=SUM(SUMIFS(J$2:J$356, $E$2:$E$356, $B$369:$B$371))} -> 146.41 | K358: {=SUM(SUMIFS(K$2:K$356, $E$2:$E$356, $B$369:$B$371))} -> 0.75 | L358: {=SUM(SUMIFS(L$2:L$356, $E$2:$E$356, $B$369:$B$371))} -> 16.32 | M358: {=SUM(SUMIFS(M$2:M$356, $E$2:$E$356, $B$369:$B$371))} -> 26.05 | O358: {=SUM(SUMIFS(O$2:O$356, $E$2:$E$356, $B$369:$B$371))} -> 0 | P358: {=SUM(SUMIFS(P$2:P$356, $E$2:$E$356, $B$369:$B$371))} -> 0 | R358: {=SUM(SUMIFS(R$2:R$356, $E$2:$E$356, $B$369:$B$371))} -> 0 | S358: {=SUM(SUMIFS(S$2:S$356, $E$2:$E$356, $B$369:$B$371))} -> 0 | T358: {=SUM(SUMIFS(T$2:T$356, $E$2:$E$356, $B$369:$B$371))} -> 0 | U358: {=SUM(SUMIFS(U$2:U$356, $E$2:$E$356, $B$369:$B$371))} -> 25 | V358: {=SUM(SUMIFS(V$2:V$356, $E$2:$E$356, $B$369:$B$371))} -> 1764 | X358: {=SUM(SUMIFS(X$2:X$356, $E$2:$E$356, $B$369:$B$371))} -> 13 | Y358: {=SUM(SUMIFS(Y$2:Y$356, $E$2:$E$356, $B$369:$B$371))} -> 882 | Z358: {=SUM(SUMIFS(Z$2:Z$356, $E$2:$E$356, $B$369:$B$371))} -> 4.58 | AA358: {=SUM(SUMIFS(AA$2:AA$356, $E$2:$E$356, $B$369:$B$371))} -> 882 | AB358: {=SUM(SUMIFS(AB$2:AB$356, $E$2:$E$356, $B$369:$B$371))} -> 245 | AC358: {=SUM(SUMIFS(AC$2:AC$356, $E$2:$E$356, $B$369:$B$371))} -> 64949.164 | AD358: {=SUM(SUMIFS(AD$2:AD$356, $E$2:$E$356, $B$369:$B$371))} -> 66960166
A359: 1003 | B359: 1003 | C359: 1003 | D359: 1003 | E359: GM1982 | F359: Land van Cuijk | G359: {=SUM(SUMIFS(G$2:G$356, $E$2:$E$356, $B$373:$B$378))} -> 28000 | H359: {=SUM(SUMIFS(H$2:H$356, $E$2:$E$356, $B$373:$B$378))} -> 1 | I359: {=SUM(SUMIFS(I$2:I$356, $E$2:$E$356, $B$373:$B$378))} -> 123.3 | J359: {=SUM(SUMIFS(J$2:J$356, $E$2:$E$356, $B$373:$B$378))} -> 355.19 | K359: {=SUM(SUMIFS(K$2:K$356, $E$2:$E$356, $B$373:$B$378))} -> 4.33 | L359: {=SUM(SUMIFS(L$2:L$356, $E$2:$E$356, $B$373:$B$378))} -> 112.81 | M359: {=SUM(SUMIFS(M$2:M$356, $E$2:$E$356, $B$373:$B$378))} -> 25.52 | O359: {=SUM(SUMIFS(O$2:O$356, $E$2:$E$356, $B$373:$B$378))} -> 4 | P359: {=SUM(SUMIFS(P$2:P$356, $E$2:$E$356, $B$373:$B$378))} -> 340.3 | R359: {=SUM(SUMIFS(R$2:R$356, $E$2:$E$356, $B$373:$B$378))} -> 4 | S359: {=SUM(SUMIFS(S$2:S$356, $E$2:$E$356, $B$373:$B$378))} -> 340.3 | T359: {=SUM(SUMIFS(T$2:T$356, $E$2:$E$356, $B$373:$B$378))} -> 4 | U359: {=SUM(SUMIFS(U$2:U$356, $E$2:$E$356, $B$373:$B$378))} -> 261 | V359: {=SUM(SUMIFS(V$2:V$356, $E$2:$E$356, $B$373:$B$378))} -> 13943.66 | X359: {=SUM(SUMIFS(X$2:X$356, $E$2:$E$356, $B$373:$B$378))} -> 132 | Y359: {=SUM(SUMIFS(Y$2:Y$356, $E$2:$E$356, $B$373:$B$378))} -> 6971.83 | Z359: {=SUM(SUMIFS(Z$2:Z$356, $E$2:$E$356, $B$373:$B$378))} -> 5.85 | AA359: {=SUM(SUMIFS(AA$2:AA$356, $E$2:$E$356, $B$373:$B$378))} -> 7312.13 | AB359: {=SUM(SUMIFS(AB$2:AB$356, $E$2:$E$356, $B$373:$B$378))} -> 2031.15 | AC359: {=SUM(SUMIFS(AC$2:AC$356, $E$2:$E$356, $B$373:$B$378))} -> 209855.06 | AD359: {=SUM(SUMIFS(AD$2:AD$356, $E$2:$E$356, $B$373:$B$378))} -> 3.5187058e+08
A360: 1004 | B360: 1004 | C360: 1004 | D360: 1004 | E360: GM1991 | F360: Maashorst | G360: {=SUM(SUMIFS(G$2:G$356, $E$2:$E$356, $B$380:$B$382))} -> 11200 | H360: {=SUM(SUMIFS(H$2:H$356, $E$2:$E$356, $B$380:$B$382))} -> 0 | I360: {=SUM(SUMIFS(I$2:I$356, $E$2:$E$356, $B$380:$B$382))} -> 51.2 | J360: {=SUM(SUMIFS(J$2:J$356, $E$2:$E$356, $B$380:$B$382))} -> 83.58 | K360: {=SUM(SUMIFS(K$2:K$356, $E$2:$E$356, $B$380:$B$382))} -> 0.48 | L360: {=SUM(SUMIFS(L$2:L$356, $E$2:$E$356, $B$380:$B$382))} -> 113.45 | M360: {=SUM(SUMIFS(M$2:M$356, $E$2:$E$356, $B$380:$B$382))} -> 1.41 | O360: {=SUM(SUMIFS(O$2:O$356, $E$2:$E$356, $B$380:$B$382))} -> 0 | P360: {=SUM(SUMIFS(P$2:P$356, $E$2:$E$356, $B$380:$B$382))} -> 0 | R360: {=SUM(SUMIFS(R$2:R$356, $E$2:$E$356, $B$380:$B$382))} -> 0 | S360: {=SUM(SUMIFS(S$2:S$356, $E$2:$E$356, $B$380:$B$382))} -> 0 | T360: {=SUM(SUMIFS(T$2:T$356, $E$2:$E$356, $B$380:$B$382))} -> 0 | U360: {=SUM(SUMIFS(U$2:U$356, $E$2:$E$356, $B$380:$B$382))} -> 80 | V360: {=SUM(SUMIFS(V$2:V$356, $E$2:$E$356, $B$380:$B$382))} -> 4273.92 | X360: {=SUM(SUMIFS(X$2:X$356, $E$2:$E$356, $B$380:$B$382))} -> 40 | Y360: {=SUM(SUMIFS(Y$2:Y$356, $E$2:$E$356, $B$380:$B$382))} -> 2136.96 | Z360: {=SUM(SUMIFS(Z$2:Z$356, $E$2:$E$356, $B$380:$B$382))} -> 1.63 | AA360: {=SUM(SUMIFS(AA$2:AA$356, $E$2:$E$356, $B$380:$B$382))} -> 2136.96 | AB360: {=SUM(SUMIFS(AB$2:AB$356, $E$2:$E$356, $B$380:$B$382))} -> 593.6 | AC360: {=SUM(SUMIFS(AC$2:AC$356, $E$2:$E$356, $B$380:$B$382))} -> 91370.954 | AD360: {=SUM(SUMIFS(AD$2:AD$356, $E$2:$E$356, $B$380:$B$382))} -> 1.3827262e+08
A361: 1005 | B361: 1005 | C361: 1005 | D361: 1005 | E361: GM1992 | F361: Voorne aan Zee | G361: {=SUM(SUMIFS(G$2:G$356, $E$2:$E$356, $B$385:$B$387))} -> 16800 | H361: {=SUM(SUMIFS(H$2:H$356, $E$2:$E$356, $B$385:$B$387))} -> 2.78 | I361: {=SUM(SUMIFS(I$2:I$356, $E$2:$E$356, $B$385:$B$387))} -> 34.45 | J361: {=SUM(SUMIFS(J$2:J$356, $E$2:$E$356, $B$385:$B$387))} -> 159.56 | K361: {=SUM(SUMIFS(K$2:K$356, $E$2:$E$356, $B$385:$B$387))} -> 0.42 | L361: {=SUM(SUMIFS(L$2:L$356, $E$2:$E$356, $B$385:$B$387))} -> 89.9 | M361: {=SUM(SUMIFS(M$2:M$356, $E$2:$E$356, $B$385:$B$387))} -> 30.61 | O361: {=SUM(SUMIFS(O$2:O$356, $E$2:$E$356, $B$385:$B$387))} -> 11 | P361: {=SUM(SUMIFS(P$2:P$356, $E$2:$E$356, $B$385:$B$387))} -> 935.83 | R361: {=SUM(SUMIFS(R$2:R$356, $E$2:$E$356, $B$385:$B$387))} -> 11 | S361: {=SUM(SUMIFS(S$2:S$356, $E$2:$E$356, $B$385:$B$387))} -> 935.83 | T361: {=SUM(SUMIFS(T$2:T$356, $E$2:$E$356, $B$385:$B$387))} -> 10.93 | U361: {=SUM(SUMIFS(U$2:U$356, $E$2:$E$356, $B$385:$B$387))} -> 100 | V361: {=SUM(SUMIFS(V$2:V$356, $E$2:$E$356, $B$385:$B$387))} -> 6696.75 | X361: {=SUM(SUMIFS(X$2:X$356, $E$2:$E$356, $B$385:$B$387))} -> 50 | Y361: {=SUM(SUMIFS(Y$2:Y$356, $E$2:$E$356, $B$385:$B$387))} -> 3348.37 | Z361: {=SUM(SUMIFS(Z$2:Z$356, $E$2:$E$356, $B$385:$B$387))} -> 5.82 | AA361: {=SUM(SUMIFS(AA$2:AA$356, $E$2:$E$356, $B$385:$B$387))} -> 4284.2 | AB361: {=SUM(SUMIFS(AB$2:AB$356, $E$2:$E$356, $B$385:$B$387))} -> 1190.06 | AC361: {=SUM(SUMIFS(AC$2:AC$356, $E$2:$E$356, $B$385:$B$387))} -> 108361.82 | AD361: {=SUM(SUMIFS(AD$2:AD$356, $E$2:$E$356, $B$385:$B$387))} -> 1.3218336e+08
B364: GM1979 | C364: Eemsdelta | G364: GM1979
B365: GM0003 | E365: Appingedam | G365: GM0003
B366: GM0024 | E366: Loppersum | G366: GM0024
B367: GM0010 | E367: Delfzijl | G367: GM0010
B369: GM1980 | C369: 1980 | D369: Dijk en Waard | G369: GM1980
B370: GM0398 | C370: Heerhugowaard | G370: GM0398
B371: GM0416 | C371: Langedijk | G371: GM0416
B373: GM1982 | C373: 1982 | D373: Land van Cuijk | G373: GM1982
B374: GM0756 | C374: Boxmeer | G374: GM0756
B375: GM1684 | C375: Cuijk | G375: GM1684
B376: GM1702 | C376: Sint Anthonis | G376: GM1702
B377: GM0815 | C377: Mill en Sint Hubert | G377: GM0815
B378: GM0786 | C378: Grave | G378: GM0786
B380: GM1991 | C380: 1991 | D380: Maashorst | G380: GM1991
B381: GM1685 | C381: Landerd | G381: GM1685
B382: GM0856 | C382: Uden | G382: GM0856
B384: GM1992 | C384: 1992 | D384: Voorne aan Zee | G384: GM1992
B385: GM0501 | C385: Brielle | G385: GM0501
B386: GM0530 | C386: Hellevoetsluis | G386: GM0530
B387: GM0614 | C387: Westvoorne | G387: GM0614

Sheet municipalities per province
A1: Gemeentecode | B1: GemeentecodeGM | C1: Gemeentenaam | D1: Provinciecode | E1: ProvinciecodePV | F1: Provincienaam | G1: RES region | H1: RES region code
A2: 1680 | B2: GM1680 | C2: Aa en Hunze | D2: 22 | E2: PV22 | F2: Drenthe | G2: {=INDEX(Gebieden_in_Nederland_2023_2403!H:H,MATCH('municipalities per province'!B2,Gebieden_in_Nederland_2023_2403!B:B,0),0)} -> Drenthe | H2: {=INDEX(Gebieden_in_Nederland_2023_2403!G:G,MATCH('municipalities per province'!B2,Gebieden_in_Nederland_2023_2403!B:B,0),0)} -> ES03
A3: 0358 | B3: GM0358 | C3: Aalsmeer | D3: 27 | E3: PV27 | F3: Noord-Holland | G3: {=INDEX(Gebieden_in_Nederland_2023_2403!H:H,MATCH('municipalities per province'!B3,Gebieden_in_Nederland_2023_2403!B:B,0),0)} -> Noord-HollandZuid | H3: {=INDEX(Gebieden_in_Nederland_2023_2403!G:G,MATCH('municipalities per province'!B3,Gebieden_in_Nederland_2023_2403!B:B,0),0)} -> ES16
A4: 0197 | B4: GM0197 | C4: Aalten | D4: 25 | E4: PV25 | F4: Gelderland | G4: {=INDEX(Gebieden_in_Nederland_2023_2403!H:H,MATCH('municipalities per province'!B4,Gebieden_in_Nederland_2023_2403!B:B,0),0)} -> Achterhoek | H4: {=INDEX(Gebieden_in_Nederland_2023_2403!G:G,MATCH('municipalities per province'!B4,Gebieden_in_Nederland_2023_2403!B:B,0),0)} -> ES07
A5: 0059 | B5: GM0059 | C5: Achtkarspelen | D5: 21 | E5: PV21 | F5: Friesland | G5: {=INDEX(Gebieden_in_Nederland_2023_2403!H:H,MATCH('municipalities per province'!B5,Gebieden_in_Nederland_2023_2403!B:B,0),0)} -> Friesland | H5: {=INDEX(Gebieden_in_Nederland_2023_2403!G:G,MATCH('municipalities per province'!B5,Gebieden_in_Nederland_2023_2403!B:B,0),0)} -> ES02
A6: 0482 | B6: GM0482 | C6: Alblasserdam | D6: 28 | E6: PV28 | F6: Zuid-Holland | G6: {=INDEX(Gebieden_in_Nederland_2023_2403!H:H,MATCH('municipalities per province'!B6,Gebieden_in_Nederland_2023_2403!B:B,0),0)} -> Drechtsteden | H6: {=INDEX(Gebieden_in_Nederland_2023_2403!G:G,MATCH('municipalities per province'!B6,Gebieden_in_Nederland_2023_2403!B:B,0),0)} -> ES18
A7: 0613 | B7: GM0613 | C7: Albrandswaard | D7: 28 | E7: PV28 | F7: Zuid-Holland | G7: {=INDEX(Gebieden_in_Nederland_2023_2403!H:H,MATCH('municipalities per province'!B7,Gebieden_in_Nederland_2023_2403!B:B,0),0)} -> Rotterdam/DenHaag | H7: {=INDEX(Gebieden_in_Nederland_2023_2403!G:G,MATCH('municipalities per province'!B7,Gebieden_in_Nederland_2023_2403!B:B,0),0)} -> ES23
A8: 0361 | B8: GM0361 | C8: Alkmaar | D8: 27 | E8: PV27 | F8: Noord-Holland | G8: {=INDEX(Gebieden_in_Nederland_2023_2403!H:H,MATCH('municipalities per province'!B8,Gebieden_in_Nederland_2023_2403!B:B,0),0)} -> Noord-HollandNoord | H8: {=INDEX(Gebieden_in_Nederland_2023_2403!G:G,MATCH('municipalities per province'!B8,Gebieden_in_Nederland_2023_2403!B:B,0),0)} -> ES15
A9: 0141 | B9: GM0141 | C9: Almelo | D9: 23 | E9: PV23 | F9: Overijssel | G9: {=INDEX(Gebieden_in_Nederland_2023_2403!H:H,MATCH('municipalities per province'!B9,Gebieden_in_Nederland_2023_2403!B:B,0),0)} -> Twente | H9: {=INDEX(Gebieden_in_Nederland_2023_2403!G:G,MATCH('municipalities per province'!B9,Gebieden_in_Nederland_2023_2403!B:B,0),0)} -> ES04
A10: 0034 | B10: GM0034 | C10: Almere | D10: 24 | E10: PV24 | F10: Flevoland | G10: {=INDEX(Gebieden_in_Nederland_2023_2403!H:H,MATCH('municipalities per province'!B10,Gebieden_in_Nederland_2023_2403!B:B,0),0)} -> Flevoland | H10: {=INDEX(Gebieden_in_Nederland_2023_2403!G:G,MATCH('municipalities per province'!B10,Gebieden_in_Nederland_2023_2403!B:B,0),0)} -> ES06
A11: 0484 | B11: GM0484 | C11: Alphen aan den Rijn | D11: 28 | E11: PV28 | F11: Zuid-Holland | G11: {=INDEX(Gebieden_in_Nederland_2023_2403!H:H,MATCH('municipalities per province'!B11,Gebieden_in_Nederland_2023_2403!B:B,0),0)} -> HollandRijnland | H11: {=INDEX(Gebieden_in_Nederland_2023_2403!G:G,MATCH('municipalities per province'!B11,Gebieden_in_Nederland_2023_2403!B:B,0),0)} -> ES21
A12: 1723 | B12: GM1723 | C12: Alphen-Chaam | D12: 30 | E12: PV30 | F12: Noord-Brabant | G12: {=INDEX(Gebieden_in_Nederland_2023_2403!H:H,MATCH('municipalities per province'!B12,Gebieden_in_Nederland_2023_2403!B:B,0),0)} -> West-Brabant | H12: {=INDEX(Gebieden_in_Nederland_2023_2403!G:G,MATCH('municipalities per province'!B12,Gebieden_in_Nederland_2023_2403!B:B,0),0)} -> ES28
A13: 1959 | B13: GM1959 | C13: Altena | D13: 30 | E13: PV30 | F13: Noord-Brabant | G13: {=INDEX(Gebieden_in_Nederland_2023_2403!H:H,MATCH('municipalities per province'!B13,Gebieden_in_Nederland_2023_2403!B:B,0),0)} -> West-Brabant | H13: {=INDEX(Gebieden_in_Nederland_2023_2403!G:G,MATCH('municipalities per province'!B13,Gebieden_in_Nederland_2023_2403!B:B,0),0)} -> ES28
... A343: 0193 | B343: GM0193 | C343: Zwolle | D343: 23 | E343: PV23 | F343: Overijssel | G343: {=INDEX(Gebieden_in_Nederland_2023_2403!H:H,MATCH('municipalities per province'!B343,Gebieden_in_Nederland_2023_2403!B:B,0),0)} -> West-Overijssel | H343: {=INDEX(Gebieden_in_Nederland_2023_2403!G:G,MATCH('municipalities per province'!B343,Gebieden_in_Nederland_2023_2403!B:B,0),0)} -> ES05

Sheet Gebieden_in_Nederland_2023_2403
A1: Gebieden in Nederland 2023
B3: Onderwerp
B4: Codes en namen van gemeenten|Code | C4: Codes en namen van gemeenten|Naam | D4: Codes en namen van gemeenten|Sortering naam | E4: Lokaliseringen van gemeenten|Provincies|Code | F4: Lokaliseringen van gemeenten|Provincies|Naam | G4: Lokaliseringen van gemeenten|Regionale Energiestrategie regio’s|Code | H4: Lokaliseringen van gemeenten|Regionale Energiestrategie regio’s|Naam
A5: Regio's | B5: code | C5: naam | D5: naam | E5: code | F5: naam | G5: code | H5: naam
A6: Aa en Hunze | B6: GM1680 | C6: AaenHunze | D6: AaenHunze | E6: PV22 | F6: Drenthe | G6: ES03 | H6: Drenthe
A7: Aalsmeer | B7: GM0358 | C7: Aalsmeer | D7: Aalsmeer | E7: PV27 | F7: Noord-Holland | G7: ES16 | H7: Noord-HollandZuid
A8: Aalten | B8: GM0197 | C8: Aalten | D8: Aalten | E8: PV25 | F8: Gelderland | G8: ES07 | H8: Achterhoek
A9: Achtkarspelen | B9: GM0059 | C9: Achtkarspelen | D9: Achtkarspelen | E9: PV21 | F9: Fryslân | G9: ES02 | H9: Friesland
A10: Alblasserdam | B10: GM0482 | C10: Alblasserdam | D10: Alblasserdam | E10: PV28 | F10: Zuid-Holland | G10: ES18 | H10: Drechtsteden
A11: Albrandswaard | B11: GM0613 | C11: Albrandswaard | D11: Albrandswaard | E11: PV28 | F11: Zuid-Holland | G11: ES23 | H11: Rotterdam/DenHaag
A12: Alkmaar | B12: GM0361 | C12: Alkmaar | D12: Alkmaar | E12: PV27 | F12: Noord-Holland | G12: ES15 | H12: Noord-HollandNoord
A13: Almelo | B13: GM0141 | C13: Almelo | D13: Almelo | E13: PV23 | F13: Overijssel | G13: ES04 | H13: Twente
A14: Almere | B14: GM0034 | C14: Almere | D14: Almere | E14: PV24 | F14: Flevoland | G14: ES06 | H14: Flevoland
A15: Alphen aan den Rijn | B15: GM0484 | C15: AlphenaandenRijn | D15: AlphenaandenRijn | E15: PV28 | F15: Zuid-Holland | G15: ES21 | H15: HollandRijnland
A16: Alphen-Chaam | B16: GM1723 | C16: Alphen-Chaam | D16: Alphen+Chaam | E16: PV30 | F16: Noord-Brabant | G16: ES28 | H16: West-Brabant
... A206: Noordwijk | B206: GM0575 | C206: Noordwijk | D206: Noordwijk | E206: PV28 | F206: Zuid-Holland | G206: ES21 | H206: HollandRijnland
A207: Nuenen, Gerwen en Nederwetten | B207: GM0820 | C207: Nuenen, Gerwen en Nederwetten | E207: PV30 | F207: Noord-Brabant | G207: ES26 | H207: MetropoolregioEindhoven
A208: Nunspeet | B208: GM0302 | C208: Nunspeet | D208: Nunspeet | E208: PV25 | F208: Gelderland | G208: ES10 | H208: Noord-Veluwe
A209: Oegstgeest | B209: GM0579 | C209: Oegstgeest | D209: Oegstgeest | E209: PV28 | F209: Zuid-Holland | G209: ES21 | H209: HollandRijnland
A210: Oirschot | B210: GM0823 | C210: Oirschot | D210: Oirschot | E210: PV30 | F210: Noord-Brabant | G210: ES26 | H210: MetropoolregioEindhoven
A211: Oisterwijk | B211: GM0824 | C211: Oisterwijk | D211: Oisterwijk | E211: PV30 | F211: Noord-Brabant | G211: ES25 | H211: HartvanBrabant
A212: Oldambt | B212: GM1895 | C212: Oldambt | D212: Oldambt | E212: PV20 | F212: Groningen | G212: ES01 | H212: Groningen
